Workbook

Sheet Blocking
H1: 1 | I1: 2 | J1: 3 | K1: 4 | L1: 5 | M1: 6 | N1: 7 | O1: 8 | P1: 9 | Q1: 10 | R1: 11 | S1: 12 | T1: 13 | U1: 14 | V1: 15 | W1: 16 | X1: 17 | Y1: 18 | Z1: 19 | AA1: 20 | AD1: TEMP | AE1: 15 | AF1: 16 | AG1: 17
A2: INVENTORY TONS | C2: =E2 -> WHSE A | D2: A | E2: =CONCATENATE("WHSE ",D2) -> WHSE A | F2: STATE | G2: A | H2: =CONCATENATE($D2,"-",H$1,$G2) -> A-1A | I2: =CONCATENATE($D2,"-",I$1,$G2) -> A-2A | J2: =CONCATENATE($D2,"-",J$1,$G2) -> A-3A | K2: =CONCATENATE($D2,"-",K$1,$G2) -> A-4A | L2: =CONCATENATE($D2,"-",L$1,$G2) -> A-5A | M2: =CONCATENATE($D2,"-",M$1,$G2) -> A-6A | N2: =CONCATENATE($D2,"-",N$1,$G2) -> A-7A | O2: =CONCATENATE($D2,"-",O$1,$G2) -> A-8A | ... AA2: =CONCATENATE($D2,"-",AA$1,$G2) -> A-20A | AC2: PCA | AD2: A | AE2: =CONCATENATE($AC2,"-",AE$1,$AD2) -> PCA-15A | AF2: =CONCATENATE($AC2,"-",AF$1,$AD2) -> PCA-16A | AG2: =CONCATENATE($AC2,"-",AG$1,$AD2) -> PCA-17A
C3: TTLs | F3: =IF(COUNTIF(G3:Z3,"ERROR")=0,"CLEAR",COUNTIF(G3:Z3,"ERROR")&" ERRORS") -> CLEAR | G3: BLOCK | H3: =IFERROR(__xludf.DUMMYFUNCTION("IFERROR(IF(COUNTA(UNIQUE(FILTER(RC_IN[BLOCK],RC_IN[BLOCK LOC]=H2,RC_IN[STATE]<>""CLOSED"")))>1,""ERROR"",INDEX(UNIQUE(FILTER(RC_IN[BLOCK],RC_IN[BLOCK LOC]=H2,RC_IN[STATE]<>""CLOSED"")),1)),"""") "),"FEB-26-BLK3") -> FEB-26-BLK3 | I3: =IFERROR(__xludf.DUMMYFUNCTION("IFERROR(IF(COUNTA(UNIQUE(FILTER(RC_IN[BLOCK],RC_IN[BLOCK LOC]=I2,RC_IN[STATE]<>""CLOSED"")))>1,""ERROR"",INDEX(UNIQUE(FILTER(RC_IN[BLOCK],RC_IN[BLOCK LOC]=I2,RC_IN[STATE]<>""CLOSED"")),1)),"""") "),"FEB-26-BLK11") -> FEB-26-BLK11 | J3: =IFERROR(__xludf.DUMMYFUNCTION("IFERROR(IF(COUNTA(UNIQUE(FILTER(RC_IN[BLOCK],RC_IN[BLOCK LOC]=J2,RC_IN[STATE]<>""CLOSED"")))>1,""ERROR"",INDEX(UNIQUE(FILTER(RC_IN[BLOCK],RC_IN[BLOCK LOC]=J2,RC_IN[STATE]<>""CLOSED"")),1)),"""") "),"MARCH-26-BLK4") -> MARCH-26-BLK4 | K3: =IFERROR(__xludf.DUMMYFUNCTION("IFERROR(IF(COUNTA(UNIQUE(FILTER(RC_IN[BLOCK],RC_IN[BLOCK LOC]=K2,RC_IN[STATE]<>""CLOSED"")))>1,""ERROR"",INDEX(UNIQUE(FILTER(RC_IN[BLOCK],RC_IN[BLOCK LOC]=K2,RC_IN[STATE]<>""CLOSED"")),1)),"""") "),"MARCH-26-BLK13") -> MARCH-26-BLK13 | L3: =IFERROR(__xludf.DUMMYFUNCTION("IFERROR(IF(COUNTA(UNIQUE(FILTER(RC_IN[BLOCK],RC_IN[BLOCK LOC]=L2,RC_IN[STATE]<>""CLOSED"")))>1,""ERROR"",INDEX(UNIQUE(FILTER(RC_IN[BLOCK],RC_IN[BLOCK LOC]=L2,RC_IN[STATE]<>""CLOSED"")),1)),"""") "),"MARCH-26-BLK17") -> MARCH-26-BLK17 | M3: =IFERROR(__xludf.DUMMYFUNCTION("IFERROR(IF(COUNTA(UNIQUE(FILTER(RC_IN[BLOCK],RC_IN[BLOCK LOC]=M2,RC_IN[STATE]<>""CLOSED"")))>1,""ERROR"",INDEX(UNIQUE(FILTER(RC_IN[BLOCK],RC_IN[BLOCK LOC]=M2,RC_IN[STATE]<>""CLOSED"")),1)),"""") "),"FEB-26-BLK6") -> FEB-26-BLK6 | N3: =IFERROR(__xludf.DUMMYFUNCTION("IFERROR(IF(COUNTA(UNIQUE(FILTER(RC_IN[BLOCK],RC_IN[BLOCK LOC]=N2,RC_IN[STATE]<>""CLOSED"")))>1,""ERROR"",INDEX(UNIQUE(FILTER(RC_IN[BLOCK],RC_IN[BLOCK LOC]=N2,RC_IN[STATE]<>""CLOSED"")),1)),"""") "),"JAN-26-BLK22") -> JAN-26-BLK22 | O3: =IFERROR(__xludf.DUMMYFUNCTION("IFERROR(IF(COUNTA(UNIQUE(FILTER(RC_IN[BLOCK],RC_IN[BLOCK LOC]=O2,RC_IN[STATE]<>""CLOSED"")))>1,""ERROR"",INDEX(UNIQUE(FILTER(RC_IN[BLOCK],RC_IN[BLOCK LOC]=O2,RC_IN[STATE]<>""CLOSED"")),1)),"""") "),"JAN-26-BLK14") -> JAN-26-BLK14 | P3: =IFERROR(__xludf.DUMMYFUNCTION("IFERROR(IF(COUNTA(UNIQUE(FILTER(RC_IN[BLOCK],RC_IN[BLOCK LOC]=P2,RC_IN[STATE]<>""CLOSED"")))>1,""ERROR"",INDEX(UNIQUE(FILTER(RC_IN[BLOCK],RC_IN[BLOCK LOC]=P2,RC_IN[STATE]<>""CLOSED"")),1)),"""") "),"JAN-26-BLK1") -> JAN-26-BLK1 | Q3: =IFERROR(__xludf.DUMMYFUNCTION("IFERROR(IF(COUNTA(UNIQUE(FILTER(RC_IN[BLOCK],RC_IN[BLOCK LOC]=Q2,RC_IN[STATE]<>""CLOSED"")))>1,""ERROR"",INDEX(UNIQUE(FILTER(RC_IN[BLOCK],RC_IN[BLOCK LOC]=Q2,RC_IN[STATE]<>""CLOSED"")),1)),"""") "),"") | R3: =IFERROR(__xludf.DUMMYFUNCTION("IFERROR(IF(COUNTA(UNIQUE(FILTER(RC_IN[BLOCK],RC_IN[BLOCK LOC]=R2,RC_IN[STATE]<>""CLOSED"")))>1,""ERROR"",INDEX(UNIQUE(FILTER(RC_IN[BLOCK],RC_IN[BLOCK LOC]=R2,RC_IN[STATE]<>""CLOSED"")),1)),"""") "),"JAN-26-BLK15") -> JAN-26-BLK15 | S3: =IFERROR(__xludf.DUMMYFUNCTION("IFERROR(IF(COUNTA(UNIQUE(FILTER(RC_IN[BLOCK],RC_IN[BLOCK LOC]=S2,RC_IN[STATE]<>""CLOSED"")))>1,""ERROR"",INDEX(UNIQUE(FILTER(RC_IN[BLOCK],RC_IN[BLOCK LOC]=S2,RC_IN[STATE]<>""CLOSED"")),1)),"""") "),"NOV-24-BLK9") -> NOV-24-BLK9 | T3: =IFERROR(__xludf.DUMMYFUNCTION("IFERROR(IF(COUNTA(UNIQUE(FILTER(RC_IN[BLOCK],RC_IN[BLOCK LOC]=T2,RC_IN[STATE]<>""CLOSED"")))>1,""ERROR"",INDEX(UNIQUE(FILTER(RC_IN[BLOCK],RC_IN[BLOCK LOC]=T2,RC_IN[STATE]<>""CLOSED"")),1)),"""") "),"OCT-24-BLK3") -> OCT-24-BLK3 | U3: =IFERROR(__xludf.DUMMYFUNCTION("IFERROR(IF(COUNTA(UNIQUE(FILTER(RC_IN[BLOCK],RC_IN[BLOCK LOC]=U2,RC_IN[STATE]<>""CLOSED"")))>1,""ERROR"",INDEX(UNIQUE(FILTER(RC_IN[BLOCK],RC_IN[BLOCK LOC]=U2,RC_IN[STATE]<>""CLOSED"")),1)),"""") "),"AUG-24-BLK6") -> AUG-24-BLK6 | V3: =IFERROR(__xludf.DUMMYFUNCTION("IFERROR(IF(COUNTA(UNIQUE(FILTER(RC_IN[BLOCK],RC_IN[BLOCK LOC]=V2,RC_IN[STATE]<>""CLOSED"")))>1,""ERROR"",INDEX(UNIQUE(FILTER(RC_IN[BLOCK],RC_IN[BLOCK LOC]=V2,RC_IN[STATE]<>""CLOSED"")),1)),"""") "),"AUG-24-BLK3") -> AUG-24-BLK3 | W3: =IFERROR(__xludf.DUMMYFUNCTION("IFERROR(IF(COUNTA(UNIQUE(FILTER(RC_IN[BLOCK],RC_IN[BLOCK LOC]=W2,RC_IN[STATE]<>""CLOSED"")))>1,""ERROR"",INDEX(UNIQUE(FILTER(RC_IN[BLOCK],RC_IN[BLOCK LOC]=W2,RC_IN[STATE]<>""CLOSED"")),1)),"""") "),"") | X3: =IFERROR(__xludf.DUMMYFUNCTION("IFERROR(IF(COUNTA(UNIQUE(FILTER(RC_IN[BLOCK],RC_IN[BLOCK LOC]=X2,RC_IN[STATE]<>""CLOSED"")))>1,""ERROR"",INDEX(UNIQUE(FILTER(RC_IN[BLOCK],RC_IN[BLOCK LOC]=X2,RC_IN[STATE]<>""CLOSED"")),1)),"""") "),"JUNE-26-BLK1") -> JUNE-26-BLK1 | Y3: =IFERROR(__xludf.DUMMYFUNCTION("IFERROR(IF(COUNTA(UNIQUE(FILTER(RC_IN[BLOCK],RC_IN[BLOCK LOC]=Y2,RC_IN[STATE]<>""CLOSED"")))>1,""ERROR"",INDEX(UNIQUE(FILTER(RC_IN[BLOCK],RC_IN[BLOCK LOC]=Y2,RC_IN[STATE]<>""CLOSED"")),1)),"""") "),"MAY-26-BLK8") -> MAY-26-BLK8 | Z3: =IFERROR(__xludf.DUMMYFUNCTION("IFERROR(IF(COUNTA(UNIQUE(FILTER(RC_IN[BLOCK],RC_IN[BLOCK LOC]=Z2,RC_IN[STATE]<>""CLOSED"")))>1,""ERROR"",INDEX(UNIQUE(FILTER(RC_IN[BLOCK],RC_IN[BLOCK LOC]=Z2,RC_IN[STATE]<>""CLOSED"")),1)),"""") "),"MAY-26-BLK4") -> MAY-26-BLK4 | AA3: =IFERROR(__xludf.DUMMYFUNCTION("IFERROR(IF(COUNTA(UNIQUE(FILTER(RC_IN[BLOCK],RC_IN[BLOCK LOC]=AA2,RC_IN[STATE]<>""CLOSED"")))>1,""ERROR"",INDEX(UNIQUE(FILTER(RC_IN[BLOCK],RC_IN[BLOCK LOC]=AA2,RC_IN[STATE]<>""CLOSED"")),1)),"""") "),"APRIL-26-BLK7") -> APRIL-26-BLK7 | AD3: BLOCK | AE3: =IFERROR(__xludf.DUMMYFUNCTION("IFERROR(IF(COUNTA(UNIQUE(FILTER(RC_IN[BLOCK],RC_IN[BLOCK LOC]=AE2,RC_IN[STATE]<>""CLOSED"")))>1,""ERROR"",INDEX(UNIQUE(FILTER(RC_IN[BLOCK],RC_IN[BLOCK LOC]=AE2,RC_IN[STATE]<>""CLOSED"")),1)),"""") "),"") | AF3: =IFERROR(__xludf.DUMMYFUNCTION("IFERROR(IF(COUNTA(UNIQUE(FILTER(RC_IN[BLOCK],RC_IN[BLOCK LOC]=AF2,RC_IN[STATE]<>""CLOSED"")))>1,""ERROR"",INDEX(UNIQUE(FILTER(RC_IN[BLOCK],RC_IN[BLOCK LOC]=AF2,RC_IN[STATE]<>""CLOSED"")),1)),"""") "),"") | AG3: =IFERROR(__xludf.DUMMYFUNCTION("IFERROR(IF(COUNTA(UNIQUE(FILTER(RC_IN[BLOCK],RC_IN[BLOCK LOC]=AG2,RC_IN[STATE]<>""CLOSED"")))>1,""ERROR"",INDEX(UNIQUE(FILTER(RC_IN[BLOCK],RC_IN[BLOCK LOC]=AG2,RC_IN[STATE]<>""CLOSED"")),1)),"""") "),"")
A4: =SUM(C19,C32,C44,C69)/1000 -> 10293.922 | C4: =sum(H4:AA4) -> 1219668 | G4: BALANCE | H4: =SUMIFS(RC_IN[WT],RC_IN[BLOCK],H3,RC_IN[BLOCK LOC],H2)-SUMIFS(RC_OUT[WT],RC_OUT[BLOCK],H3,RC_OUT[BLOCK LOC],H2) -> 73575 | I4: =SUMIFS(RC_IN[WT],RC_IN[BLOCK],I3,RC_IN[BLOCK LOC],I2)-SUMIFS(RC_OUT[WT],RC_OUT[BLOCK],I3,RC_OUT[BLOCK LOC],I2) -> 63115 | J4: =SUMIFS(RC_IN[WT],RC_IN[BLOCK],J3,RC_IN[BLOCK LOC],J2)-SUMIFS(RC_OUT[WT],RC_OUT[BLOCK],J3,RC_OUT[BLOCK LOC],J2) -> 73580 | K4: =SUMIFS(RC_IN[WT],RC_IN[BLOCK],K3,RC_IN[BLOCK LOC],K2)-SUMIFS(RC_OUT[WT],RC_OUT[BLOCK],K3,RC_OUT[BLOCK LOC],K2) -> 75370 | L4: =SUMIFS(RC_IN[WT],RC_IN[BLOCK],L3,RC_IN[BLOCK LOC],L2)-SUMIFS(RC_OUT[WT],RC_OUT[BLOCK],L3,RC_OUT[BLOCK LOC],L2) -> 74995 | M4: =SUMIFS(RC_IN[WT],RC_IN[BLOCK],M3,RC_IN[BLOCK LOC],M2)-SUMIFS(RC_OUT[WT],RC_OUT[BLOCK],M3,RC_OUT[BLOCK LOC],M2) -> 59850 | N4: =SUMIFS(RC_IN[WT],RC_IN[BLOCK],N3,RC_IN[BLOCK LOC],N2)-SUMIFS(RC_OUT[WT],RC_OUT[BLOCK],N3,RC_OUT[BLOCK LOC],N2) -> 56234 | O4: =SUMIFS(RC_IN[WT],RC_IN[BLOCK],O3,RC_IN[BLOCK LOC],O2)-SUMIFS(RC_OUT[WT],RC_OUT[BLOCK],O3,RC_OUT[BLOCK LOC],O2) -> 59235 | ... AA4: =SUMIFS(RC_IN[WT],RC_IN[BLOCK],AA3,RC_IN[BLOCK LOC],AA2)-SUMIFS(RC_OUT[WT],RC_OUT[BLOCK],AA3,RC_OUT[BLOCK LOC],AA2) -> 60290 | AC4: =sum(AE4:AG4) -> 0 | AD4: BALANCE | AE4: =SUMIFS(RC_IN[WT],RC_IN[BLOCK],AE3,RC_IN[BLOCK LOC],AE2)-SUMIFS(RC_OUT[WT],RC_OUT[BLOCK],AE3,RC_OUT[BLOCK LOC],AE2) -> 0 | AF4: =SUMIFS(RC_IN[WT],RC_IN[BLOCK],AF3,RC_IN[BLOCK LOC],AF2)-SUMIFS(RC_OUT[WT],RC_OUT[BLOCK],AF3,RC_OUT[BLOCK LOC],AF2) -> 0 | AG4: =SUMIFS(RC_IN[WT],RC_IN[BLOCK],AG3,RC_IN[BLOCK LOC],AG2)-SUMIFS(RC_OUT[WT],RC_OUT[BLOCK],AG3,RC_OUT[BLOCK LOC],AG2) -> 0
A5: =sum(AC4,AC10,AC16,AC23,AC29,AC35)/1000 -> 0 | G5: BD | H5: =IFERROR(__xludf.DUMMYFUNCTION("IFERROR(SUMPRODUCT(FILTER(RC_IN[ASTM],RC_IN[BLOCK]=H3,RC_IN[BLOCK LOC]=H2),FILTER(RC_IN[WT],RC_IN[BLOCK]=H3,RC_IN[BLOCK LOC]=H2))/SUM(FILTER(RC_IN[WT],RC_IN[BLOCK]=H3,RC_IN[BLOCK LOC]=H2)),"""") "),0.5762532110091743) -> 0.57625321 | I5: =IFERROR(__xludf.DUMMYFUNCTION("IFERROR(SUMPRODUCT(FILTER(RC_IN[ASTM],RC_IN[BLOCK]=I3,RC_IN[BLOCK LOC]=I2),FILTER(RC_IN[WT],RC_IN[BLOCK]=I3,RC_IN[BLOCK LOC]=I2))/SUM(FILTER(RC_IN[WT],RC_IN[BLOCK]=I3,RC_IN[BLOCK LOC]=I2)),"""") "),0.5749999999999998) -> 0.575 | J5: =IFERROR(__xludf.DUMMYFUNCTION("IFERROR(SUMPRODUCT(FILTER(RC_IN[ASTM],RC_IN[BLOCK]=J3,RC_IN[BLOCK LOC]=J2),FILTER(RC_IN[WT],RC_IN[BLOCK]=J3,RC_IN[BLOCK LOC]=J2))/SUM(FILTER(RC_IN[WT],RC_IN[BLOCK]=J3,RC_IN[BLOCK LOC]=J2)),"""") "),0.5758032073933134) -> 0.57580321 | K5: =IFERROR(__xludf.DUMMYFUNCTION("IFERROR(SUMPRODUCT(FILTER(RC_IN[ASTM],RC_IN[BLOCK]=K3,RC_IN[BLOCK LOC]=K2),FILTER(RC_IN[WT],RC_IN[BLOCK]=K3,RC_IN[BLOCK LOC]=K2))/SUM(FILTER(RC_IN[WT],RC_IN[BLOCK]=K3,RC_IN[BLOCK LOC]=K2)),"""") "),0.5755880323736234) -> 0.57558803 | L5: =IFERROR(__xludf.DUMMYFUNCTION("IFERROR(SUMPRODUCT(FILTER(RC_IN[ASTM],RC_IN[BLOCK]=L3,RC_IN[BLOCK LOC]=L2),FILTER(RC_IN[WT],RC_IN[BLOCK]=L3,RC_IN[BLOCK LOC]=L2))/SUM(FILTER(RC_IN[WT],RC_IN[BLOCK]=L3,RC_IN[BLOCK LOC]=L2)),"""") "),0.5757370491366092) -> 0.57573705 | M5: =IFERROR(__xludf.DUMMYFUNCTION("IFERROR(SUMPRODUCT(FILTER(RC_IN[ASTM],RC_IN[BLOCK]=M3,RC_IN[BLOCK LOC]=M2),FILTER(RC_IN[WT],RC_IN[BLOCK]=M3,RC_IN[BLOCK LOC]=M2))/SUM(FILTER(RC_IN[WT],RC_IN[BLOCK]=M3,RC_IN[BLOCK LOC]=M2)),"""") "),0.5622988304093567) -> 0.56229883 | N5: =IFERROR(__xludf.DUMMYFUNCTION("IFERROR(SUMPRODUCT(FILTER(RC_IN[ASTM],RC_IN[BLOCK]=N3,RC_IN[BLOCK LOC]=N2),FILTER(RC_IN[WT],RC_IN[BLOCK]=N3,RC_IN[BLOCK LOC]=N2))/SUM(FILTER(RC_IN[WT],RC_IN[BLOCK]=N3,RC_IN[BLOCK LOC]=N2)),"""") "),0.5707482661734893) -> 0.57074827 | O5: =IFERROR(__xludf.DUMMYFUNCTION("IFERROR(SUMPRODUCT(FILTER(RC_IN[ASTM],RC_IN[BLOCK]=O3,RC_IN[BLOCK LOC]=O2),FILTER(RC_IN[WT],RC_IN[BLOCK]=O3,RC_IN[BLOCK LOC]=O2))/SUM(FILTER(RC_IN[WT],RC_IN[BLOCK]=O3,RC_IN[BLOCK LOC]=O2)),"""") "),0.5715036718156494) -> 0.57150367 | P5: =IFERROR(__xludf.DUMMYFUNCTION("IFERROR(SUMPRODUCT(FILTER(RC_IN[ASTM],RC_IN[BLOCK]=P3,RC_IN[BLOCK LOC]=P2),FILTER(RC_IN[WT],RC_IN[BLOCK]=P3,RC_IN[BLOCK LOC]=P2))/SUM(FILTER(RC_IN[WT],RC_IN[BLOCK]=P3,RC_IN[BLOCK LOC]=P2)),"""") "),0.5736095493406752) -> 0.57360955 | Q5: =IFERROR(__xludf.DUMMYFUNCTION("IFERROR(SUMPRODUCT(FILTER(RC_IN[ASTM],RC_IN[BLOCK]=Q3,RC_IN[BLOCK LOC]=Q2),FILTER(RC_IN[WT],RC_IN[BLOCK]=Q3,RC_IN[BLOCK LOC]=Q2))/SUM(FILTER(RC_IN[WT],RC_IN[BLOCK]=Q3,RC_IN[BLOCK LOC]=Q2)),"""") ")," ") | R5: =IFERROR(__xludf.DUMMYFUNCTION("IFERROR(SUMPRODUCT(FILTER(RC_IN[ASTM],RC_IN[BLOCK]=R3,RC_IN[BLOCK LOC]=R2),FILTER(RC_IN[WT],RC_IN[BLOCK]=R3,RC_IN[BLOCK LOC]=R2))/SUM(FILTER(RC_IN[WT],RC_IN[BLOCK]=R3,RC_IN[BLOCK LOC]=R2)),"""") "),0.5754747543575137) -> 0.57547475 | S5: =IFERROR(__xludf.DUMMYFUNCTION("IFERROR(SUMPRODUCT(FILTER(RC_IN[ASTM],RC_IN[BLOCK]=S3,RC_IN[BLOCK LOC]=S2),FILTER(RC_IN[WT],RC_IN[BLOCK]=S3,RC_IN[BLOCK LOC]=S2))/SUM(FILTER(RC_IN[WT],RC_IN[BLOCK]=S3,RC_IN[BLOCK LOC]=S2)),"""") "),0.5740059252196417) -> 0.57400593 | T5: =IFERROR(__xludf.DUMMYFUNCTION("IFERROR(SUMPRODUCT(FILTER(RC_IN[ASTM],RC_IN[BLOCK]=T3,RC_IN[BLOCK LOC]=T2),FILTER(RC_IN[WT],RC_IN[BLOCK]=T3,RC_IN[BLOCK LOC]=T2))/SUM(FILTER(RC_IN[WT],RC_IN[BLOCK]=T3,RC_IN[BLOCK LOC]=T2)),"""") "),0.5736047269763651) -> 0.57360473 | U5: =IFERROR(__xludf.DUMMYFUNCTION("IFERROR(SUMPRODUCT(FILTER(RC_IN[ASTM],RC_IN[BLOCK]=U3,RC_IN[BLOCK LOC]=U2),FILTER(RC_IN[WT],RC_IN[BLOCK]=U3,RC_IN[BLOCK LOC]=U2))/SUM(FILTER(RC_IN[WT],RC_IN[BLOCK]=U3,RC_IN[BLOCK LOC]=U2)),"""") "),0.5757271632913186) -> 0.57572716 | V5: =IFERROR(__xludf.DUMMYFUNCTION("IFERROR(SUMPRODUCT(FILTER(RC_IN[ASTM],RC_IN[BLOCK]=V3,RC_IN[BLOCK LOC]=V2),FILTER(RC_IN[WT],RC_IN[BLOCK]=V3,RC_IN[BLOCK LOC]=V2))/SUM(FILTER(RC_IN[WT],RC_IN[BLOCK]=V3,RC_IN[BLOCK LOC]=V2)),"""") "),0.5765278441850653) -> 0.57652784 | W5: =IFERROR(__xludf.DUMMYFUNCTION("IFERROR(SUMPRODUCT(FILTER(RC_IN[ASTM],RC_IN[BLOCK]=W3,RC_IN[BLOCK LOC]=W2),FILTER(RC_IN[WT],RC_IN[BLOCK]=W3,RC_IN[BLOCK LOC]=W2))/SUM(FILTER(RC_IN[WT],RC_IN[BLOCK]=W3,RC_IN[BLOCK LOC]=W2)),"""") ")," ") | X5: =IFERROR(__xludf.DUMMYFUNCTION("IFERROR(SUMPRODUCT(FILTER(RC_IN[ASTM],RC_IN[BLOCK]=X3,RC_IN[BLOCK LOC]=X2),FILTER(RC_IN[WT],RC_IN[BLOCK]=X3,RC_IN[BLOCK LOC]=X2))/SUM(FILTER(RC_IN[WT],RC_IN[BLOCK]=X3,RC_IN[BLOCK LOC]=X2)),"""") "),0.5748650041794371) -> 0.574865 | Y5: =IFERROR(__xludf.DUMMYFUNCTION("IFERROR(SUMPRODUCT(FILTER(RC_IN[ASTM],RC_IN[BLOCK]=Y3,RC_IN[BLOCK LOC]=Y2),FILTER(RC_IN[WT],RC_IN[BLOCK]=Y3,RC_IN[BLOCK LOC]=Y2))/SUM(FILTER(RC_IN[WT],RC_IN[BLOCK]=Y3,RC_IN[BLOCK LOC]=Y2)),"""") "),0.5745620289418149) -> 0.57456203 | Z5: =IFERROR(__xludf.DUMMYFUNCTION("IFERROR(SUMPRODUCT(FILTER(RC_IN[ASTM],RC_IN[BLOCK]=Z3,RC_IN[BLOCK LOC]=Z2),FILTER(RC_IN[WT],RC_IN[BLOCK]=Z3,RC_IN[BLOCK LOC]=Z2))/SUM(FILTER(RC_IN[WT],RC_IN[BLOCK]=Z3,RC_IN[BLOCK LOC]=Z2)),"""") "),0.575) -> 0.575 | AA5: =IFERROR(__xludf.DUMMYFUNCTION("IFERROR(SUMPRODUCT(FILTER(RC_IN[ASTM],RC_IN[BLOCK]=AA3,RC_IN[BLOCK LOC]=AA2),FILTER(RC_IN[WT],RC_IN[BLOCK]=AA3,RC_IN[BLOCK LOC]=AA2))/SUM(FILTER(RC_IN[WT],RC_IN[BLOCK]=AA3,RC_IN[BLOCK LOC]=AA2)),"""") "),0.5746329407862) -> 0.57463294 | AD5: BD | AE5: =IFERROR(__xludf.DUMMYFUNCTION("IFERROR(SUMPRODUCT(FILTER(RC_IN[ASTM],RC_IN[BLOCK]=AE3,RC_IN[BLOCK LOC]=AE2),FILTER(RC_IN[WT],RC_IN[BLOCK]=AE3,RC_IN[BLOCK LOC]=AE2))/SUM(FILTER(RC_IN[WT],RC_IN[BLOCK]=AE3,RC_IN[BLOCK LOC]=AE2)),"""") ")," ") | AF5: =IFERROR(__xludf.DUMMYFUNCTION("IFERROR(SUMPRODUCT(FILTER(RC_IN[ASTM],RC_IN[BLOCK]=AF3,RC_IN[BLOCK LOC]=AF2),FILTER(RC_IN[WT],RC_IN[BLOCK]=AF3,RC_IN[BLOCK LOC]=AF2))/SUM(FILTER(RC_IN[WT],RC_IN[BLOCK]=AF3,RC_IN[BLOCK LOC]=AF2)),"""") ")," ") | AG5: =IFERROR(__xludf.DUMMYFUNCTION("IFERROR(SUMPRODUCT(FILTER(RC_IN[ASTM],RC_IN[BLOCK]=AG3,RC_IN[BLOCK LOC]=AG2),FILTER(RC_IN[WT],RC_IN[BLOCK]=AG3,RC_IN[BLOCK LOC]=AG2))/SUM(FILTER(RC_IN[WT],RC_IN[BLOCK]=AG3,RC_IN[BLOCK LOC]=AG2)),"""") ")," ")
A6: =sum(A4:A5) -> 10293.922 | G6: ASH | H6: =IFERROR(__xludf.DUMMYFUNCTION("IFERROR(SUMPRODUCT(FILTER(RC_IN[ASH],RC_IN[BLOCK]=H3,RC_IN[BLOCK LOC]=H2),FILTER(RC_IN[WT],RC_IN[BLOCK]=H3,RC_IN[BLOCK LOC]=H2))/SUM(FILTER(RC_IN[WT],RC_IN[BLOCK]=H3,RC_IN[BLOCK LOC]=H2)),"""") "),3.0958246687054025) -> 3.0958247 | I6: =IFERROR(__xludf.DUMMYFUNCTION("IFERROR(SUMPRODUCT(FILTER(RC_IN[ASH],RC_IN[BLOCK]=I3,RC_IN[BLOCK LOC]=I2),FILTER(RC_IN[WT],RC_IN[BLOCK]=I3,RC_IN[BLOCK LOC]=I2))/SUM(FILTER(RC_IN[WT],RC_IN[BLOCK]=I3,RC_IN[BLOCK LOC]=I2)),"""") "),3.4638445694367426) -> 3.4638446 | J6: =IFERROR(__xludf.DUMMYFUNCTION("IFERROR(SUMPRODUCT(FILTER(RC_IN[ASH],RC_IN[BLOCK]=J3,RC_IN[BLOCK LOC]=J2),FILTER(RC_IN[WT],RC_IN[BLOCK]=J3,RC_IN[BLOCK LOC]=J2))/SUM(FILTER(RC_IN[WT],RC_IN[BLOCK]=J3,RC_IN[BLOCK LOC]=J2)),"""") "),3.725118238651808) -> 3.7251182 | K6: =IFERROR(__xludf.DUMMYFUNCTION("IFERROR(SUMPRODUCT(FILTER(RC_IN[ASH],RC_IN[BLOCK]=K3,RC_IN[BLOCK LOC]=K2),FILTER(RC_IN[WT],RC_IN[BLOCK]=K3,RC_IN[BLOCK LOC]=K2))/SUM(FILTER(RC_IN[WT],RC_IN[BLOCK]=K3,RC_IN[BLOCK LOC]=K2)),"""") "),3.1888496749369777) -> 3.1888497 | L6: =IFERROR(__xludf.DUMMYFUNCTION("IFERROR(SUMPRODUCT(FILTER(RC_IN[ASH],RC_IN[BLOCK]=L3,RC_IN[BLOCK LOC]=L2),FILTER(RC_IN[WT],RC_IN[BLOCK]=L3,RC_IN[BLOCK LOC]=L2))/SUM(FILTER(RC_IN[WT],RC_IN[BLOCK]=L3,RC_IN[BLOCK LOC]=L2)),"""") "),3.1420141342756183) -> 3.1420141 | M6: =IFERROR(__xludf.DUMMYFUNCTION("IFERROR(SUMPRODUCT(FILTER(RC_IN[ASH],RC_IN[BLOCK]=M3,RC_IN[BLOCK LOC]=M2),FILTER(RC_IN[WT],RC_IN[BLOCK]=M3,RC_IN[BLOCK LOC]=M2))/SUM(FILTER(RC_IN[WT],RC_IN[BLOCK]=M3,RC_IN[BLOCK LOC]=M2)),"""") "),3.2542046783625733) -> 3.2542047 | N6: =IFERROR(__xludf.DUMMYFUNCTION("IFERROR(SUMPRODUCT(FILTER(RC_IN[ASH],RC_IN[BLOCK]=N3,RC_IN[BLOCK LOC]=N2),FILTER(RC_IN[WT],RC_IN[BLOCK]=N3,RC_IN[BLOCK LOC]=N2))/SUM(FILTER(RC_IN[WT],RC_IN[BLOCK]=N3,RC_IN[BLOCK LOC]=N2)),"""") "),3.469668527936836) -> 3.4696685 | O6: =IFERROR(__xludf.DUMMYFUNCTION("IFERROR(SUMPRODUCT(FILTER(RC_IN[ASH],RC_IN[BLOCK]=O3,RC_IN[BLOCK LOC]=O2),FILTER(RC_IN[WT],RC_IN[BLOCK]=O3,RC_IN[BLOCK LOC]=O2))/SUM(FILTER(RC_IN[WT],RC_IN[BLOCK]=O3,RC_IN[BLOCK LOC]=O2)),"""") "),3.0674322613319824) -> 3.0674323 | P6: =IFERROR(__xludf.DUMMYFUNCTION("IFERROR(SUMPRODUCT(FILTER(RC_IN[ASH],RC_IN[BLOCK]=P3,RC_IN[BLOCK LOC]=P2),FILTER(RC_IN[WT],RC_IN[BLOCK]=P3,RC_IN[BLOCK LOC]=P2))/SUM(FILTER(RC_IN[WT],RC_IN[BLOCK]=P3,RC_IN[BLOCK LOC]=P2)),"""") "),3.5674221127372845) -> 3.5674221 | Q6: =IFERROR(__xludf.DUMMYFUNCTION("IFERROR(SUMPRODUCT(FILTER(RC_IN[ASH],RC_IN[BLOCK]=Q3,RC_IN[BLOCK LOC]=Q2),FILTER(RC_IN[WT],RC_IN[BLOCK]=Q3,RC_IN[BLOCK LOC]=Q2))/SUM(FILTER(RC_IN[WT],RC_IN[BLOCK]=Q3,RC_IN[BLOCK LOC]=Q2)),"""") ")," ") | R6: =IFERROR(__xludf.DUMMYFUNCTION("IFERROR(SUMPRODUCT(FILTER(RC_IN[ASH],RC_IN[BLOCK]=R3,RC_IN[BLOCK LOC]=R2),FILTER(RC_IN[WT],RC_IN[BLOCK]=R3,RC_IN[BLOCK LOC]=R2))/SUM(FILTER(RC_IN[WT],RC_IN[BLOCK]=R3,RC_IN[BLOCK LOC]=R2)),"""") "),3.4031038853077855) -> 3.4031039 | S6: =IFERROR(__xludf.DUMMYFUNCTION("IFERROR(SUMPRODUCT(FILTER(RC_IN[ASH],RC_IN[BLOCK]=S3,RC_IN[BLOCK LOC]=S2),FILTER(RC_IN[WT],RC_IN[BLOCK]=S3,RC_IN[BLOCK LOC]=S2))/SUM(FILTER(RC_IN[WT],RC_IN[BLOCK]=S3,RC_IN[BLOCK LOC]=S2)),"""") "),2.0514070693999864) -> 2.0514071 | T6: =IFERROR(__xludf.DUMMYFUNCTION("IFERROR(SUMPRODUCT(FILTER(RC_IN[ASH],RC_IN[BLOCK]=T3,RC_IN[BLOCK LOC]=T2),FILTER(RC_IN[WT],RC_IN[BLOCK]=T3,RC_IN[BLOCK LOC]=T2))/SUM(FILTER(RC_IN[WT],RC_IN[BLOCK]=T3,RC_IN[BLOCK LOC]=T2)),"""") "),2.5430489903106044) -> 2.543049 | U6: =IFERROR(__xludf.DUMMYFUNCTION("IFERROR(SUMPRODUCT(FILTER(RC_IN[ASH],RC_IN[BLOCK]=U3,RC_IN[BLOCK LOC]=U2),FILTER(RC_IN[WT],RC_IN[BLOCK]=U3,RC_IN[BLOCK LOC]=U2))/SUM(FILTER(RC_IN[WT],RC_IN[BLOCK]=U3,RC_IN[BLOCK LOC]=U2)),"""") "),2.6870365387338904) -> 2.6870365 | V6: =IFERROR(__xludf.DUMMYFUNCTION("IFERROR(SUMPRODUCT(FILTER(RC_IN[ASH],RC_IN[BLOCK]=V3,RC_IN[BLOCK LOC]=V2),FILTER(RC_IN[WT],RC_IN[BLOCK]=V3,RC_IN[BLOCK LOC]=V2))/SUM(FILTER(RC_IN[WT],RC_IN[BLOCK]=V3,RC_IN[BLOCK LOC]=V2)),"""") "),2.6077330895795248) -> 2.6077331 | W6: =IFERROR(__xludf.DUMMYFUNCTION("IFERROR(SUMPRODUCT(FILTER(RC_IN[ASH],RC_IN[BLOCK]=W3,RC_IN[BLOCK LOC]=W2),FILTER(RC_IN[WT],RC_IN[BLOCK]=W3,RC_IN[BLOCK LOC]=W2))/SUM(FILTER(RC_IN[WT],RC_IN[BLOCK]=W3,RC_IN[BLOCK LOC]=W2)),"""") ")," ") | X6: =IFERROR(__xludf.DUMMYFUNCTION("IFERROR(SUMPRODUCT(FILTER(RC_IN[ASH],RC_IN[BLOCK]=X3,RC_IN[BLOCK LOC]=X2),FILTER(RC_IN[WT],RC_IN[BLOCK]=X3,RC_IN[BLOCK LOC]=X2))/SUM(FILTER(RC_IN[WT],RC_IN[BLOCK]=X3,RC_IN[BLOCK LOC]=X2)),"""") "),3.4152772359988854) -> 3.4152772 | Y6: =IFERROR(__xludf.DUMMYFUNCTION("IFERROR(SUMPRODUCT(FILTER(RC_IN[ASH],RC_IN[BLOCK]=Y3,RC_IN[BLOCK LOC]=Y2),FILTER(RC_IN[WT],RC_IN[BLOCK]=Y3,RC_IN[BLOCK LOC]=Y2))/SUM(FILTER(RC_IN[WT],RC_IN[BLOCK]=Y3,RC_IN[BLOCK LOC]=Y2)),"""") "),3.2884684956285803) -> 3.2884685 | Z6: =IFERROR(__xludf.DUMMYFUNCTION("IFERROR(SUMPRODUCT(FILTER(RC_IN[ASH],RC_IN[BLOCK]=Z3,RC_IN[BLOCK LOC]=Z2),FILTER(RC_IN[WT],RC_IN[BLOCK]=Z3,RC_IN[BLOCK LOC]=Z2))/SUM(FILTER(RC_IN[WT],RC_IN[BLOCK]=Z3,RC_IN[BLOCK LOC]=Z2)),"""") "),3.3988768690139874) -> 3.3988769 | AA6: =IFERROR(__xludf.DUMMYFUNCTION("IFERROR(SUMPRODUCT(FILTER(RC_IN[ASH],RC_IN[BLOCK]=AA3,RC_IN[BLOCK LOC]=AA2),FILTER(RC_IN[WT],RC_IN[BLOCK]=AA3,RC_IN[BLOCK LOC]=AA2))/SUM(FILTER(RC_IN[WT],RC_IN[BLOCK]=AA3,RC_IN[BLOCK LOC]=AA2)),"""") "),3.228454138331398) -> 3.2284541 | AD6: ASH | AE6: =IFERROR(__xludf.DUMMYFUNCTION("IFERROR(SUMPRODUCT(FILTER(RC_IN[ASH],RC_IN[BLOCK]=AE3,RC_IN[BLOCK LOC]=AE2),FILTER(RC_IN[WT],RC_IN[BLOCK]=AE3,RC_IN[BLOCK LOC]=AE2))/SUM(FILTER(RC_IN[WT],RC_IN[BLOCK]=AE3,RC_IN[BLOCK LOC]=AE2)),"""") ")," ") | AF6: =IFERROR(__xludf.DUMMYFUNCTION("IFERROR(SUMPRODUCT(FILTER(RC_IN[ASH],RC_IN[BLOCK]=AF3,RC_IN[BLOCK LOC]=AF2),FILTER(RC_IN[WT],RC_IN[BLOCK]=AF3,RC_IN[BLOCK LOC]=AF2))/SUM(FILTER(RC_IN[WT],RC_IN[BLOCK]=AF3,RC_IN[BLOCK LOC]=AF2)),"""") ")," ") | AG6: =IFERROR(__xludf.DUMMYFUNCTION("IFERROR(SUMPRODUCT(FILTER(RC_IN[ASH],RC_IN[BLOCK]=AG3,RC_IN[BLOCK LOC]=AG2),FILTER(RC_IN[WT],RC_IN[BLOCK]=AG3,RC_IN[BLOCK LOC]=AG2))/SUM(FILTER(RC_IN[WT],RC_IN[BLOCK]=AG3,RC_IN[BLOCK LOC]=AG2)),"""") ")," ")
G7: MC | H7: =IFERROR(__xludf.DUMMYFUNCTION("IFERROR(SUMPRODUCT(FILTER(RC_IN[MC],RC_IN[BLOCK]=H3,RC_IN[BLOCK LOC]=H2),FILTER(RC_IN[WT],RC_IN[BLOCK]=H3,RC_IN[BLOCK LOC]=H2)) / SUM(FILTER(RC_IN[WT],RC_IN[BLOCK]=H3,RC_IN[BLOCK LOC]=H2)),"""") "),11.482941216445804) -> 11.482941 | I7: =IFERROR(__xludf.DUMMYFUNCTION("IFERROR(SUMPRODUCT(FILTER(RC_IN[MC],RC_IN[BLOCK]=I3,RC_IN[BLOCK LOC]=I2),FILTER(RC_IN[WT],RC_IN[BLOCK]=I3,RC_IN[BLOCK LOC]=I2)) / SUM(FILTER(RC_IN[WT],RC_IN[BLOCK]=I3,RC_IN[BLOCK LOC]=I2)),"""") "),11.467759645092292) -> 11.46776 | J7: =IFERROR(__xludf.DUMMYFUNCTION("IFERROR(SUMPRODUCT(FILTER(RC_IN[MC],RC_IN[BLOCK]=J3,RC_IN[BLOCK LOC]=J2),FILTER(RC_IN[WT],RC_IN[BLOCK]=J3,RC_IN[BLOCK LOC]=J2)) / SUM(FILTER(RC_IN[WT],RC_IN[BLOCK]=J3,RC_IN[BLOCK LOC]=J2)),"""") "),11.53014406088611) -> 11.530144 | K7: =IFERROR(__xludf.DUMMYFUNCTION("IFERROR(SUMPRODUCT(FILTER(RC_IN[MC],RC_IN[BLOCK]=K3,RC_IN[BLOCK LOC]=K2),FILTER(RC_IN[WT],RC_IN[BLOCK]=K3,RC_IN[BLOCK LOC]=K2)) / SUM(FILTER(RC_IN[WT],RC_IN[BLOCK]=K3,RC_IN[BLOCK LOC]=K2)),"""") "),11.65735969218522) -> 11.65736 | L7: =IFERROR(__xludf.DUMMYFUNCTION("IFERROR(SUMPRODUCT(FILTER(RC_IN[MC],RC_IN[BLOCK]=L3,RC_IN[BLOCK LOC]=L2),FILTER(RC_IN[WT],RC_IN[BLOCK]=L3,RC_IN[BLOCK LOC]=L2)) / SUM(FILTER(RC_IN[WT],RC_IN[BLOCK]=L3,RC_IN[BLOCK LOC]=L2)),"""") "),11.683928261884125) -> 11.683928 | M7: =IFERROR(__xludf.DUMMYFUNCTION("IFERROR(SUMPRODUCT(FILTER(RC_IN[MC],RC_IN[BLOCK]=M3,RC_IN[BLOCK LOC]=M2),FILTER(RC_IN[WT],RC_IN[BLOCK]=M3,RC_IN[BLOCK LOC]=M2)) / SUM(FILTER(RC_IN[WT],RC_IN[BLOCK]=M3,RC_IN[BLOCK LOC]=M2)),"""") "),9.941983291562238) -> 9.9419833 | N7: =IFERROR(__xludf.DUMMYFUNCTION("IFERROR(SUMPRODUCT(FILTER(RC_IN[MC],RC_IN[BLOCK]=N3,RC_IN[BLOCK LOC]=N2),FILTER(RC_IN[WT],RC_IN[BLOCK]=N3,RC_IN[BLOCK LOC]=N2)) / SUM(FILTER(RC_IN[WT],RC_IN[BLOCK]=N3,RC_IN[BLOCK LOC]=N2)),"""") "),11.452809688089058) -> 11.45281 | O7: =IFERROR(__xludf.DUMMYFUNCTION("IFERROR(SUMPRODUCT(FILTER(RC_IN[MC],RC_IN[BLOCK]=O3,RC_IN[BLOCK LOC]=O2),FILTER(RC_IN[WT],RC_IN[BLOCK]=O3,RC_IN[BLOCK LOC]=O2)) / SUM(FILTER(RC_IN[WT],RC_IN[BLOCK]=O3,RC_IN[BLOCK LOC]=O2)),"""") "),10.231458597113193) -> 10.231459 | P7: =IFERROR(__xludf.DUMMYFUNCTION("IFERROR(SUMPRODUCT(FILTER(RC_IN[MC],RC_IN[BLOCK]=P3,RC_IN[BLOCK LOC]=P2),FILTER(RC_IN[WT],RC_IN[BLOCK]=P3,RC_IN[BLOCK LOC]=P2)) / SUM(FILTER(RC_IN[WT],RC_IN[BLOCK]=P3,RC_IN[BLOCK LOC]=P2)),"""") "),9.493826257064192) -> 9.4938263 | Q7: =IFERROR(__xludf.DUMMYFUNCTION("IFERROR(SUMPRODUCT(FILTER(RC_IN[MC],RC_IN[BLOCK]=Q3,RC_IN[BLOCK LOC]=Q2),FILTER(RC_IN[WT],RC_IN[BLOCK]=Q3,RC_IN[BLOCK LOC]=Q2)) / SUM(FILTER(RC_IN[WT],RC_IN[BLOCK]=Q3,RC_IN[BLOCK LOC]=Q2)),"""") "),"") | R7: =IFERROR(__xludf.DUMMYFUNCTION("IFERROR(SUMPRODUCT(FILTER(RC_IN[MC],RC_IN[BLOCK]=R3,RC_IN[BLOCK LOC]=R2),FILTER(RC_IN[WT],RC_IN[BLOCK]=R3,RC_IN[BLOCK LOC]=R2)) / SUM(FILTER(RC_IN[WT],RC_IN[BLOCK]=R3,RC_IN[BLOCK LOC]=R2)),"""") "),12.239473827661866) -> 12.239474 | S7: =IFERROR(__xludf.DUMMYFUNCTION("IFERROR(SUMPRODUCT(FILTER(RC_IN[MC],RC_IN[BLOCK]=S3,RC_IN[BLOCK LOC]=S2),FILTER(RC_IN[WT],RC_IN[BLOCK]=S3,RC_IN[BLOCK LOC]=S2)) / SUM(FILTER(RC_IN[WT],RC_IN[BLOCK]=S3,RC_IN[BLOCK LOC]=S2)),"""") "),11.57316216032146) -> 11.573162 | T7: =IFERROR(__xludf.DUMMYFUNCTION("IFERROR(SUMPRODUCT(FILTER(RC_IN[MC],RC_IN[BLOCK]=T3,RC_IN[BLOCK LOC]=T2),FILTER(RC_IN[WT],RC_IN[BLOCK]=T3,RC_IN[BLOCK LOC]=T2)) / SUM(FILTER(RC_IN[WT],RC_IN[BLOCK]=T3,RC_IN[BLOCK LOC]=T2)),"""") "),11.724493344199944) -> 11.724493 | U7: =IFERROR(__xludf.DUMMYFUNCTION("IFERROR(SUMPRODUCT(FILTER(RC_IN[MC],RC_IN[BLOCK]=U3,RC_IN[BLOCK LOC]=U2),FILTER(RC_IN[WT],RC_IN[BLOCK]=U3,RC_IN[BLOCK LOC]=U2)) / SUM(FILTER(RC_IN[WT],RC_IN[BLOCK]=U3,RC_IN[BLOCK LOC]=U2)),"""") "),11.216190341311428) -> 11.21619 | V7: =IFERROR(__xludf.DUMMYFUNCTION("IFERROR(SUMPRODUCT(FILTER(RC_IN[MC],RC_IN[BLOCK]=V3,RC_IN[BLOCK LOC]=V2),FILTER(RC_IN[WT],RC_IN[BLOCK]=V3,RC_IN[BLOCK LOC]=V2)) / SUM(FILTER(RC_IN[WT],RC_IN[BLOCK]=V3,RC_IN[BLOCK LOC]=V2)),"""") "),11.02812403318802) -> 11.028124 | W7: =IFERROR(__xludf.DUMMYFUNCTION("IFERROR(SUMPRODUCT(FILTER(RC_IN[MC],RC_IN[BLOCK]=W3,RC_IN[BLOCK LOC]=W2),FILTER(RC_IN[WT],RC_IN[BLOCK]=W3,RC_IN[BLOCK LOC]=W2)) / SUM(FILTER(RC_IN[WT],RC_IN[BLOCK]=W3,RC_IN[BLOCK LOC]=W2)),"""") "),"") | X7: =IFERROR(__xludf.DUMMYFUNCTION("IFERROR(SUMPRODUCT(FILTER(RC_IN[MC],RC_IN[BLOCK]=X3,RC_IN[BLOCK LOC]=X2),FILTER(RC_IN[WT],RC_IN[BLOCK]=X3,RC_IN[BLOCK LOC]=X2)) / SUM(FILTER(RC_IN[WT],RC_IN[BLOCK]=X3,RC_IN[BLOCK LOC]=X2)),"""") "),11.517327946503203) -> 11.517328 | Y7: =IFERROR(__xludf.DUMMYFUNCTION("IFERROR(SUMPRODUCT(FILTER(RC_IN[MC],RC_IN[BLOCK]=Y3,RC_IN[BLOCK LOC]=Y2),FILTER(RC_IN[WT],RC_IN[BLOCK]=Y3,RC_IN[BLOCK LOC]=Y2)) / SUM(FILTER(RC_IN[WT],RC_IN[BLOCK]=Y3,RC_IN[BLOCK LOC]=Y2)),"""") "),11.164036780223093) -> 11.164037 | Z7: =IFERROR(__xludf.DUMMYFUNCTION("IFERROR(SUMPRODUCT(FILTER(RC_IN[MC],RC_IN[BLOCK]=Z3,RC_IN[BLOCK LOC]=Z2),FILTER(RC_IN[WT],RC_IN[BLOCK]=Z3,RC_IN[BLOCK LOC]=Z2)) / SUM(FILTER(RC_IN[WT],RC_IN[BLOCK]=Z3,RC_IN[BLOCK LOC]=Z2)),"""") "),11.353144077723421) -> 11.353144 | AA7: =IFERROR(__xludf.DUMMYFUNCTION("IFERROR(SUMPRODUCT(FILTER(RC_IN[MC],RC_IN[BLOCK]=AA3,RC_IN[BLOCK LOC]=AA2),FILTER(RC_IN[WT],RC_IN[BLOCK]=AA3,RC_IN[BLOCK LOC]=AA2)) / SUM(FILTER(RC_IN[WT],RC_IN[BLOCK]=AA3,RC_IN[BLOCK LOC]=AA2)),"""") "),11.39740918892022) -> 11.397409 | AD7: MC | AE7: =IFERROR(__xludf.DUMMYFUNCTION("IFERROR(SUMPRODUCT(FILTER(RC_IN[MC],RC_IN[BLOCK]=AE3,RC_IN[BLOCK LOC]=AE2),FILTER(RC_IN[WT],RC_IN[BLOCK]=AE3,RC_IN[BLOCK LOC]=AE2)) / SUM(FILTER(RC_IN[WT],RC_IN[BLOCK]=AE3,RC_IN[BLOCK LOC]=AE2)),"""") "),"") | AF7: =IFERROR(__xludf.DUMMYFUNCTION("IFERROR(SUMPRODUCT(FILTER(RC_IN[MC],RC_IN[BLOCK]=AF3,RC_IN[BLOCK LOC]=AF2),FILTER(RC_IN[WT],RC_IN[BLOCK]=AF3,RC_IN[BLOCK LOC]=AF2)) / SUM(FILTER(RC_IN[WT],RC_IN[BLOCK]=AF3,RC_IN[BLOCK LOC]=AF2)),"""") "),"") | AG7: =IFERROR(__xludf.DUMMYFUNCTION("IFERROR(SUMPRODUCT(FILTER(RC_IN[MC],RC_IN[BLOCK]=AG3,RC_IN[BLOCK LOC]=AG2),FILTER(RC_IN[WT],RC_IN[BLOCK]=AG3,RC_IN[BLOCK LOC]=AG2)) / SUM(FILTER(RC_IN[WT],RC_IN[BLOCK]=AG3,RC_IN[BLOCK LOC]=AG2)),"""") "),"")
D8: =D2 -> A | G8: B | H8: =CONCATENATE($D8,"-",H$1,$G8) -> A-1B | I8: =CONCATENATE($D8,"-",I$1,$G8) -> A-2B | J8: =CONCATENATE($D8,"-",J$1,$G8) -> A-3B | K8: =CONCATENATE($D8,"-",K$1,$G8) -> A-4B | L8: =CONCATENATE($D8,"-",L$1,$G8) -> A-5B | M8: =CONCATENATE($D8,"-",M$1,$G8) -> A-6B | N8: =CONCATENATE($D8,"-",N$1,$G8) -> A-7B | O8: =CONCATENATE($D8,"-",O$1,$G8) -> A-8B | ... AA8: =CONCATENATE($D8,"-",AA$1,$G8) -> A-20B | AC8: PCA | AD8: B | AE8: =CONCATENATE($AC8,"-",AE$1,$AD8) -> PCA-15B | AF8: =CONCATENATE($AC8,"-",AF$1,$AD8) -> PCA-16B | AG8: =CONCATENATE($AC8,"-",AG$1,$AD8) -> PCA-17B
F9: =IF(COUNTIF(G9:Z9,"ERROR")=0,"CLEAR",COUNTIF(G9:Z9,"ERROR")&" ERRORS") -> CLEAR | G9: BLOCK | H9: =IFERROR(__xludf.DUMMYFUNCTION("IFERROR(IF(COUNTA(UNIQUE(FILTER(RC_IN[BLOCK],RC_IN[BLOCK LOC]=H8,RC_IN[STATE]<>""CLOSED"")))>1,""ERROR"",INDEX(UNIQUE(FILTER(RC_IN[BLOCK],RC_IN[BLOCK LOC]=H8,RC_IN[STATE]<>""CLOSED"")),1)),"""") "),"FEB-26-BLK8") -> FEB-26-BLK8 | I9: =IFERROR(__xludf.DUMMYFUNCTION("IFERROR(IF(COUNTA(UNIQUE(FILTER(RC_IN[BLOCK],RC_IN[BLOCK LOC]=I8,RC_IN[STATE]<>""CLOSED"")))>1,""ERROR"",INDEX(UNIQUE(FILTER(RC_IN[BLOCK],RC_IN[BLOCK LOC]=I8,RC_IN[STATE]<>""CLOSED"")),1)),"""") "),"FEB-26-BLK16") -> FEB-26-BLK16 | J9: =IFERROR(__xludf.DUMMYFUNCTION("IFERROR(IF(COUNTA(UNIQUE(FILTER(RC_IN[BLOCK],RC_IN[BLOCK LOC]=J8,RC_IN[STATE]<>""CLOSED"")))>1,""ERROR"",INDEX(UNIQUE(FILTER(RC_IN[BLOCK],RC_IN[BLOCK LOC]=J8,RC_IN[STATE]<>""CLOSED"")),1)),"""") "),"MARCH-26-BLK10") -> MARCH-26-BLK10 | K9: =IFERROR(__xludf.DUMMYFUNCTION("IFERROR(IF(COUNTA(UNIQUE(FILTER(RC_IN[BLOCK],RC_IN[BLOCK LOC]=K8,RC_IN[STATE]<>""CLOSED"")))>1,""ERROR"",INDEX(UNIQUE(FILTER(RC_IN[BLOCK],RC_IN[BLOCK LOC]=K8,RC_IN[STATE]<>""CLOSED"")),1)),"""") "),"MARCH-26-BLK24") -> MARCH-26-BLK24 | L9: =IFERROR(__xludf.DUMMYFUNCTION("IFERROR(IF(COUNTA(UNIQUE(FILTER(RC_IN[BLOCK],RC_IN[BLOCK LOC]=L8,RC_IN[STATE]<>""CLOSED"")))>1,""ERROR"",INDEX(UNIQUE(FILTER(RC_IN[BLOCK],RC_IN[BLOCK LOC]=L8,RC_IN[STATE]<>""CLOSED"")),1)),"""") "),"MARCH-26-BLK26") -> MARCH-26-BLK26 | M9: =IFERROR(__xludf.DUMMYFUNCTION("IFERROR(IF(COUNTA(UNIQUE(FILTER(RC_IN[BLOCK],RC_IN[BLOCK LOC]=M8,RC_IN[STATE]<>""CLOSED"")))>1,""ERROR"",INDEX(UNIQUE(FILTER(RC_IN[BLOCK],RC_IN[BLOCK LOC]=M8,RC_IN[STATE]<>""CLOSED"")),1)),"""") "),"FEB-26-BLK9") -> FEB-26-BLK9 | N9: =IFERROR(__xludf.DUMMYFUNCTION("IFERROR(IF(COUNTA(UNIQUE(FILTER(RC_IN[BLOCK],RC_IN[BLOCK LOC]=N8,RC_IN[STATE]<>""CLOSED"")))>1,""ERROR"",INDEX(UNIQUE(FILTER(RC_IN[BLOCK],RC_IN[BLOCK LOC]=N8,RC_IN[STATE]<>""CLOSED"")),1)),"""") "),"FEB-26-BLK1") -> FEB-26-BLK1 | O9: =IFERROR(__xludf.DUMMYFUNCTION("IFERROR(IF(COUNTA(UNIQUE(FILTER(RC_IN[BLOCK],RC_IN[BLOCK LOC]=O8,RC_IN[STATE]<>""CLOSED"")))>1,""ERROR"",INDEX(UNIQUE(FILTER(RC_IN[BLOCK],RC_IN[BLOCK LOC]=O8,RC_IN[STATE]<>""CLOSED"")),1)),"""") "),"JAN-26-BLK18") -> JAN-26-BLK18 | P9: =IFERROR(__xludf.DUMMYFUNCTION("IFERROR(IF(COUNTA(UNIQUE(FILTER(RC_IN[BLOCK],RC_IN[BLOCK LOC]=P8,RC_IN[STATE]<>""CLOSED"")))>1,""ERROR"",INDEX(UNIQUE(FILTER(RC_IN[BLOCK],RC_IN[BLOCK LOC]=P8,RC_IN[STATE]<>""CLOSED"")),1)),"""") "),"JAN-26-BLK3") -> JAN-26-BLK3 | Q9: =IFERROR(__xludf.DUMMYFUNCTION("IFERROR(IF(COUNTA(UNIQUE(FILTER(RC_IN[BLOCK],RC_IN[BLOCK LOC]=Q8,RC_IN[STATE]<>""CLOSED"")))>1,""ERROR"",INDEX(UNIQUE(FILTER(RC_IN[BLOCK],RC_IN[BLOCK LOC]=Q8,RC_IN[STATE]<>""CLOSED"")),1)),"""") "),"") | R9: =IFERROR(__xludf.DUMMYFUNCTION("IFERROR(IF(COUNTA(UNIQUE(FILTER(RC_IN[BLOCK],RC_IN[BLOCK LOC]=R8,RC_IN[STATE]<>""CLOSED"")))>1,""ERROR"",INDEX(UNIQUE(FILTER(RC_IN[BLOCK],RC_IN[BLOCK LOC]=R8,RC_IN[STATE]<>""CLOSED"")),1)),"""") "),"") | S9: =IFERROR(__xludf.DUMMYFUNCTION("IFERROR(IF(COUNTA(UNIQUE(FILTER(RC_IN[BLOCK],RC_IN[BLOCK LOC]=S8,RC_IN[STATE]<>""CLOSED"")))>1,""ERROR"",INDEX(UNIQUE(FILTER(RC_IN[BLOCK],RC_IN[BLOCK LOC]=S8,RC_IN[STATE]<>""CLOSED"")),1)),"""") "),"DEC-24-BLK1") -> DEC-24-BLK1 | T9: =IFERROR(__xludf.DUMMYFUNCTION("IFERROR(IF(COUNTA(UNIQUE(FILTER(RC_IN[BLOCK],RC_IN[BLOCK LOC]=T8,RC_IN[STATE]<>""CLOSED"")))>1,""ERROR"",INDEX(UNIQUE(FILTER(RC_IN[BLOCK],RC_IN[BLOCK LOC]=T8,RC_IN[STATE]<>""CLOSED"")),1)),"""") "),"NOV-24-BLK1") -> NOV-24-BLK1 | U9: =IFERROR(__xludf.DUMMYFUNCTION("IFERROR(IF(COUNTA(UNIQUE(FILTER(RC_IN[BLOCK],RC_IN[BLOCK LOC]=U8,RC_IN[STATE]<>""CLOSED"")))>1,""ERROR"",INDEX(UNIQUE(FILTER(RC_IN[BLOCK],RC_IN[BLOCK LOC]=U8,RC_IN[STATE]<>""CLOSED"")),1)),"""") "),"SEPT-24-BLK1") -> SEPT-24-BLK1 | V9: =IFERROR(__xludf.DUMMYFUNCTION("IFERROR(IF(COUNTA(UNIQUE(FILTER(RC_IN[BLOCK],RC_IN[BLOCK LOC]=V8,RC_IN[STATE]<>""CLOSED"")))>1,""ERROR"",INDEX(UNIQUE(FILTER(RC_IN[BLOCK],RC_IN[BLOCK LOC]=V8,RC_IN[STATE]<>""CLOSED"")),1)),"""") "),"SEPT-24-BLK4") -> SEPT-24-BLK4 | W9: =IFERROR(__xludf.DUMMYFUNCTION("IFERROR(IF(COUNTA(UNIQUE(FILTER(RC_IN[BLOCK],RC_IN[BLOCK LOC]=W8,RC_IN[STATE]<>""CLOSED"")))>1,""ERROR"",INDEX(UNIQUE(FILTER(RC_IN[BLOCK],RC_IN[BLOCK LOC]=W8,RC_IN[STATE]<>""CLOSED"")),1)),"""") "),"") | X9: =IFERROR(__xludf.DUMMYFUNCTION("IFERROR(IF(COUNTA(UNIQUE(FILTER(RC_IN[BLOCK],RC_IN[BLOCK LOC]=X8,RC_IN[STATE]<>""CLOSED"")))>1,""ERROR"",INDEX(UNIQUE(FILTER(RC_IN[BLOCK],RC_IN[BLOCK LOC]=X8,RC_IN[STATE]<>""CLOSED"")),1)),"""") "),"JUNE-26-BLK2") -> JUNE-26-BLK2 | Y9: =IFERROR(__xludf.DUMMYFUNCTION("IFERROR(IF(COUNTA(UNIQUE(FILTER(RC_IN[BLOCK],RC_IN[BLOCK LOC]=Y8,RC_IN[STATE]<>""CLOSED"")))>1,""ERROR"",INDEX(UNIQUE(FILTER(RC_IN[BLOCK],RC_IN[BLOCK LOC]=Y8,RC_IN[STATE]<>""CLOSED"")),1)),"""") "),"MAY-26-BLK12") -> MAY-26-BLK12 | Z9: =IFERROR(__xludf.DUMMYFUNCTION("IFERROR(IF(COUNTA(UNIQUE(FILTER(RC_IN[BLOCK],RC_IN[BLOCK LOC]=Z8,RC_IN[STATE]<>""CLOSED"")))>1,""ERROR"",INDEX(UNIQUE(FILTER(RC_IN[BLOCK],RC_IN[BLOCK LOC]=Z8,RC_IN[STATE]<>""CLOSED"")),1)),"""") "),"MAY-26-BLK6") -> MAY-26-BLK6 | AA9: =IFERROR(__xludf.DUMMYFUNCTION("IFERROR(IF(COUNTA(UNIQUE(FILTER(RC_IN[BLOCK],RC_IN[BLOCK LOC]=AA8,RC_IN[STATE]<>""CLOSED"")))>1,""ERROR"",INDEX(UNIQUE(FILTER(RC_IN[BLOCK],RC_IN[BLOCK LOC]=AA8,RC_IN[STATE]<>""CLOSED"")),1)),"""") "),"MAY-26-BLK2") -> MAY-26-BLK2 | AD9: BLOCK | AE9: =IFERROR(__xludf.DUMMYFUNCTION("IFERROR(IF(COUNTA(UNIQUE(FILTER(RC_IN[BLOCK],RC_IN[BLOCK LOC]=AE8,RC_IN[STATE]<>""CLOSED"")))>1,""ERROR"",INDEX(UNIQUE(FILTER(RC_IN[BLOCK],RC_IN[BLOCK LOC]=AE8,RC_IN[STATE]<>""CLOSED"")),1)),"""") "),"") | AF9: =IFERROR(__xludf.DUMMYFUNCTION("IFERROR(IF(COUNTA(UNIQUE(FILTER(RC_IN[BLOCK],RC_IN[BLOCK LOC]=AF8,RC_IN[STATE]<>""CLOSED"")))>1,""ERROR"",INDEX(UNIQUE(FILTER(RC_IN[BLOCK],RC_IN[BLOCK LOC]=AF8,RC_IN[STATE]<>""CLOSED"")),1)),"""") "),"") | AG9: =IFERROR(__xludf.DUMMYFUNCTION("IFERROR(IF(COUNTA(UNIQUE(FILTER(RC_IN[BLOCK],RC_IN[BLOCK LOC]=AG8,RC_IN[STATE]<>""CLOSED"")))>1,""ERROR"",INDEX(UNIQUE(FILTER(RC_IN[BLOCK],RC_IN[BLOCK LOC]=AG8,RC_IN[STATE]<>""CLOSED"")),1)),"""") "),"")
C10: =sum(H10:AA10) -> 1111494 | G10: BALANCE | H10: =SUMIFS(RC_IN[WT],RC_IN[BLOCK],H9,RC_IN[BLOCK LOC],H8)-SUMIFS(RC_OUT[WT],RC_OUT[BLOCK],H9,RC_OUT[BLOCK LOC],H8) -> 71835 | I10: =SUMIFS(RC_IN[WT],RC_IN[BLOCK],I9,RC_IN[BLOCK LOC],I8)-SUMIFS(RC_OUT[WT],RC_OUT[BLOCK],I9,RC_OUT[BLOCK LOC],I8) -> 70843 | J10: =SUMIFS(RC_IN[WT],RC_IN[BLOCK],J9,RC_IN[BLOCK LOC],J8)-SUMIFS(RC_OUT[WT],RC_OUT[BLOCK],J9,RC_OUT[BLOCK LOC],J8) -> 74510 | K10: =SUMIFS(RC_IN[WT],RC_IN[BLOCK],K9,RC_IN[BLOCK LOC],K8)-SUMIFS(RC_OUT[WT],RC_OUT[BLOCK],K9,RC_OUT[BLOCK LOC],K8) -> 71325 | L10: =SUMIFS(RC_IN[WT],RC_IN[BLOCK],L9,RC_IN[BLOCK LOC],L8)-SUMIFS(RC_OUT[WT],RC_OUT[BLOCK],L9,RC_OUT[BLOCK LOC],L8) -> 27238 | M10: =SUMIFS(RC_IN[WT],RC_IN[BLOCK],M9,RC_IN[BLOCK LOC],M8)-SUMIFS(RC_OUT[WT],RC_OUT[BLOCK],M9,RC_OUT[BLOCK LOC],M8) -> 52860 | N10: =SUMIFS(RC_IN[WT],RC_IN[BLOCK],N9,RC_IN[BLOCK LOC],N8)-SUMIFS(RC_OUT[WT],RC_OUT[BLOCK],N9,RC_OUT[BLOCK LOC],N8) -> 56185 | O10: =SUMIFS(RC_IN[WT],RC_IN[BLOCK],O9,RC_IN[BLOCK LOC],O8)-SUMIFS(RC_OUT[WT],RC_OUT[BLOCK],O9,RC_OUT[BLOCK LOC],O8) -> 59220 | ... AA10: =SUMIFS(RC_IN[WT],RC_IN[BLOCK],AA9,RC_IN[BLOCK LOC],AA8)-SUMIFS(RC_OUT[WT],RC_OUT[BLOCK],AA9,RC_OUT[BLOCK LOC],AA8) -> 70200 | AC10: =sum(AE10:AG10) -> 0 | AD10: BALANCE | AE10: =SUMIFS(RC_IN[WT],RC_IN[BLOCK],AE9,RC_IN[BLOCK LOC],AE8)-SUMIFS(RC_OUT[WT],RC_OUT[BLOCK],AE9,RC_OUT[BLOCK LOC],AE8) -> 0 | AF10: =SUMIFS(RC_IN[WT],RC_IN[BLOCK],AF9,RC_IN[BLOCK LOC],AF8)-SUMIFS(RC_OUT[WT],RC_OUT[BLOCK],AF9,RC_OUT[BLOCK LOC],AF8) -> 0 | AG10: =SUMIFS(RC_IN[WT],RC_IN[BLOCK],AG9,RC_IN[BLOCK LOC],AG8)-SUMIFS(RC_OUT[WT],RC_OUT[BLOCK],AG9,RC_OUT[BLOCK LOC],AG8) -> 0
G11: BD | H11: =IFERROR(__xludf.DUMMYFUNCTION("IFERROR(SUMPRODUCT(FILTER(RC_IN[ASTM],RC_IN[BLOCK]=H9,RC_IN[BLOCK LOC]=H8),FILTER(RC_IN[WT],RC_IN[BLOCK]=H9,RC_IN[BLOCK LOC]=H8))/SUM(FILTER(RC_IN[WT],RC_IN[BLOCK]=H9,RC_IN[BLOCK LOC]=H8)),"""") "),0.5764917519315097) -> 0.57649175 | I11: =IFERROR(__xludf.DUMMYFUNCTION("IFERROR(SUMPRODUCT(FILTER(RC_IN[ASTM],RC_IN[BLOCK]=I9,RC_IN[BLOCK LOC]=I8),FILTER(RC_IN[WT],RC_IN[BLOCK]=I9,RC_IN[BLOCK LOC]=I8))/SUM(FILTER(RC_IN[WT],RC_IN[BLOCK]=I9,RC_IN[BLOCK LOC]=I8)),"""") "),0.5764266758889375) -> 0.57642668 | J11: =IFERROR(__xludf.DUMMYFUNCTION("IFERROR(SUMPRODUCT(FILTER(RC_IN[ASTM],RC_IN[BLOCK]=J9,RC_IN[BLOCK LOC]=J8),FILTER(RC_IN[WT],RC_IN[BLOCK]=J9,RC_IN[BLOCK LOC]=J8))/SUM(FILTER(RC_IN[WT],RC_IN[BLOCK]=J9,RC_IN[BLOCK LOC]=J8)),"""") "),0.5757031942021205) -> 0.57570319 | K11: =IFERROR(__xludf.DUMMYFUNCTION("IFERROR(SUMPRODUCT(FILTER(RC_IN[ASTM],RC_IN[BLOCK]=K9,RC_IN[BLOCK LOC]=K8),FILTER(RC_IN[WT],RC_IN[BLOCK]=K9,RC_IN[BLOCK LOC]=K8))/SUM(FILTER(RC_IN[WT],RC_IN[BLOCK]=K9,RC_IN[BLOCK LOC]=K8)),"""") "),0.5772870662460567) -> 0.57728707 | L11: =IFERROR(__xludf.DUMMYFUNCTION("IFERROR(SUMPRODUCT(FILTER(RC_IN[ASTM],RC_IN[BLOCK]=L9,RC_IN[BLOCK LOC]=L8),FILTER(RC_IN[WT],RC_IN[BLOCK]=L9,RC_IN[BLOCK LOC]=L8))/SUM(FILTER(RC_IN[WT],RC_IN[BLOCK]=L9,RC_IN[BLOCK LOC]=L8)),"""") "),0.5743908005863055) -> 0.5743908 | M11: =IFERROR(__xludf.DUMMYFUNCTION("IFERROR(SUMPRODUCT(FILTER(RC_IN[ASTM],RC_IN[BLOCK]=M9,RC_IN[BLOCK LOC]=M8),FILTER(RC_IN[WT],RC_IN[BLOCK]=M9,RC_IN[BLOCK LOC]=M8))/SUM(FILTER(RC_IN[WT],RC_IN[BLOCK]=M9,RC_IN[BLOCK LOC]=M8)),"""") "),0.5666802875520243) -> 0.56668029 | N11: =IFERROR(__xludf.DUMMYFUNCTION("IFERROR(SUMPRODUCT(FILTER(RC_IN[ASTM],RC_IN[BLOCK]=N9,RC_IN[BLOCK LOC]=N8),FILTER(RC_IN[WT],RC_IN[BLOCK]=N9,RC_IN[BLOCK LOC]=N8))/SUM(FILTER(RC_IN[WT],RC_IN[BLOCK]=N9,RC_IN[BLOCK LOC]=N8)),"""") "),0.5603077333807956) -> 0.56030773 | O11: =IFERROR(__xludf.DUMMYFUNCTION("IFERROR(SUMPRODUCT(FILTER(RC_IN[ASTM],RC_IN[BLOCK]=O9,RC_IN[BLOCK LOC]=O8),FILTER(RC_IN[WT],RC_IN[BLOCK]=O9,RC_IN[BLOCK LOC]=O8))/SUM(FILTER(RC_IN[WT],RC_IN[BLOCK]=O9,RC_IN[BLOCK LOC]=O8)),"""") "),0.5671612630867949) -> 0.56716126 | P11: =IFERROR(__xludf.DUMMYFUNCTION("IFERROR(SUMPRODUCT(FILTER(RC_IN[ASTM],RC_IN[BLOCK]=P9,RC_IN[BLOCK LOC]=P8),FILTER(RC_IN[WT],RC_IN[BLOCK]=P9,RC_IN[BLOCK LOC]=P8))/SUM(FILTER(RC_IN[WT],RC_IN[BLOCK]=P9,RC_IN[BLOCK LOC]=P8)),"""") "),0.5708741009976026) -> 0.5708741 | Q11: =IFERROR(__xludf.DUMMYFUNCTION("IFERROR(SUMPRODUCT(FILTER(RC_IN[ASTM],RC_IN[BLOCK]=Q9,RC_IN[BLOCK LOC]=Q8),FILTER(RC_IN[WT],RC_IN[BLOCK]=Q9,RC_IN[BLOCK LOC]=Q8))/SUM(FILTER(RC_IN[WT],RC_IN[BLOCK]=Q9,RC_IN[BLOCK LOC]=Q8)),"""") ")," ") | R11: =IFERROR(__xludf.DUMMYFUNCTION("IFERROR(SUMPRODUCT(FILTER(RC_IN[ASTM],RC_IN[BLOCK]=R9,RC_IN[BLOCK LOC]=R8),FILTER(RC_IN[WT],RC_IN[BLOCK]=R9,RC_IN[BLOCK LOC]=R8))/SUM(FILTER(RC_IN[WT],RC_IN[BLOCK]=R9,RC_IN[BLOCK LOC]=R8)),"""") ")," ") | S11: =IFERROR(__xludf.DUMMYFUNCTION("IFERROR(SUMPRODUCT(FILTER(RC_IN[ASTM],RC_IN[BLOCK]=S9,RC_IN[BLOCK LOC]=S8),FILTER(RC_IN[WT],RC_IN[BLOCK]=S9,RC_IN[BLOCK LOC]=S8))/SUM(FILTER(RC_IN[WT],RC_IN[BLOCK]=S9,RC_IN[BLOCK LOC]=S8)),"""") "),0.5735974218677548) -> 0.57359742 | T11: =IFERROR(__xludf.DUMMYFUNCTION("IFERROR(SUMPRODUCT(FILTER(RC_IN[ASTM],RC_IN[BLOCK]=T9,RC_IN[BLOCK LOC]=T8),FILTER(RC_IN[WT],RC_IN[BLOCK]=T9,RC_IN[BLOCK LOC]=T8))/SUM(FILTER(RC_IN[WT],RC_IN[BLOCK]=T9,RC_IN[BLOCK LOC]=T8)),"""") "),0.5729976603680104) -> 0.57299766 | U11: =IFERROR(__xludf.DUMMYFUNCTION("IFERROR(SUMPRODUCT(FILTER(RC_IN[ASTM],RC_IN[BLOCK]=U9,RC_IN[BLOCK LOC]=U8),FILTER(RC_IN[WT],RC_IN[BLOCK]=U9,RC_IN[BLOCK LOC]=U8))/SUM(FILTER(RC_IN[WT],RC_IN[BLOCK]=U9,RC_IN[BLOCK LOC]=U8)),"""") "),0.5773150381842836) -> 0.57731504 | V11: =IFERROR(__xludf.DUMMYFUNCTION("IFERROR(SUMPRODUCT(FILTER(RC_IN[ASTM],RC_IN[BLOCK]=V9,RC_IN[BLOCK LOC]=V8),FILTER(RC_IN[WT],RC_IN[BLOCK]=V9,RC_IN[BLOCK LOC]=V8))/SUM(FILTER(RC_IN[WT],RC_IN[BLOCK]=V9,RC_IN[BLOCK LOC]=V8)),"""") "),0.5765271877655055) -> 0.57652719 | W11: =IFERROR(__xludf.DUMMYFUNCTION("IFERROR(SUMPRODUCT(FILTER(RC_IN[ASTM],RC_IN[BLOCK]=W9,RC_IN[BLOCK LOC]=W8),FILTER(RC_IN[WT],RC_IN[BLOCK]=W9,RC_IN[BLOCK LOC]=W8))/SUM(FILTER(RC_IN[WT],RC_IN[BLOCK]=W9,RC_IN[BLOCK LOC]=W8)),"""") ")," ") | X11: =IFERROR(__xludf.DUMMYFUNCTION("IFERROR(SUMPRODUCT(FILTER(RC_IN[ASTM],RC_IN[BLOCK]=X9,RC_IN[BLOCK LOC]=X8),FILTER(RC_IN[WT],RC_IN[BLOCK]=X9,RC_IN[BLOCK LOC]=X8))/SUM(FILTER(RC_IN[WT],RC_IN[BLOCK]=X9,RC_IN[BLOCK LOC]=X8)),"""") "),0.5744618865527871) -> 0.57446189 | Y11: =IFERROR(__xludf.DUMMYFUNCTION("IFERROR(SUMPRODUCT(FILTER(RC_IN[ASTM],RC_IN[BLOCK]=Y9,RC_IN[BLOCK LOC]=Y8),FILTER(RC_IN[WT],RC_IN[BLOCK]=Y9,RC_IN[BLOCK LOC]=Y8))/SUM(FILTER(RC_IN[WT],RC_IN[BLOCK]=Y9,RC_IN[BLOCK LOC]=Y8)),"""") "),0.5772454099132422) -> 0.57724541 | Z11: =IFERROR(__xludf.DUMMYFUNCTION("IFERROR(SUMPRODUCT(FILTER(RC_IN[ASTM],RC_IN[BLOCK]=Z9,RC_IN[BLOCK LOC]=Z8),FILTER(RC_IN[WT],RC_IN[BLOCK]=Z9,RC_IN[BLOCK LOC]=Z8))/SUM(FILTER(RC_IN[WT],RC_IN[BLOCK]=Z9,RC_IN[BLOCK LOC]=Z8)),"""") "),0.5781333996023857) -> 0.5781334 | AA11: =IFERROR(__xludf.DUMMYFUNCTION("IFERROR(SUMPRODUCT(FILTER(RC_IN[ASTM],RC_IN[BLOCK]=AA9,RC_IN[BLOCK LOC]=AA8),FILTER(RC_IN[WT],RC_IN[BLOCK]=AA9,RC_IN[BLOCK LOC]=AA8))/SUM(FILTER(RC_IN[WT],RC_IN[BLOCK]=AA9,RC_IN[BLOCK LOC]=AA8)),"""") "),0.5747487891737891) -> 0.57474879 | AD11: BD | AE11: =IFERROR(__xludf.DUMMYFUNCTION("IFERROR(SUMPRODUCT(FILTER(RC_IN[ASTM],RC_IN[BLOCK]=AE9,RC_IN[BLOCK LOC]=AE8),FILTER(RC_IN[WT],RC_IN[BLOCK]=AE9,RC_IN[BLOCK LOC]=AE8))/SUM(FILTER(RC_IN[WT],RC_IN[BLOCK]=AE9,RC_IN[BLOCK LOC]=AE8)),"""") ")," ") | AF11: =IFERROR(__xludf.DUMMYFUNCTION("IFERROR(SUMPRODUCT(FILTER(RC_IN[ASTM],RC_IN[BLOCK]=AF9,RC_IN[BLOCK LOC]=AF8),FILTER(RC_IN[WT],RC_IN[BLOCK]=AF9,RC_IN[BLOCK LOC]=AF8))/SUM(FILTER(RC_IN[WT],RC_IN[BLOCK]=AF9,RC_IN[BLOCK LOC]=AF8)),"""") ")," ") | AG11: =IFERROR(__xludf.DUMMYFUNCTION("IFERROR(SUMPRODUCT(FILTER(RC_IN[ASTM],RC_IN[BLOCK]=AG9,RC_IN[BLOCK LOC]=AG8),FILTER(RC_IN[WT],RC_IN[BLOCK]=AG9,RC_IN[BLOCK LOC]=AG8))/SUM(FILTER(RC_IN[WT],RC_IN[BLOCK]=AG9,RC_IN[BLOCK LOC]=AG8)),"""") ")," ")
G12: ASH | H12: =IFERROR(__xludf.DUMMYFUNCTION("IFERROR(SUMPRODUCT(FILTER(RC_IN[ASH],RC_IN[BLOCK]=H9,RC_IN[BLOCK LOC]=H8),FILTER(RC_IN[WT],RC_IN[BLOCK]=H9,RC_IN[BLOCK LOC]=H8))/SUM(FILTER(RC_IN[WT],RC_IN[BLOCK]=H9,RC_IN[BLOCK LOC]=H8)),"""") "),3.144030068907914) -> 3.1440301 | I12: =IFERROR(__xludf.DUMMYFUNCTION("IFERROR(SUMPRODUCT(FILTER(RC_IN[ASH],RC_IN[BLOCK]=I9,RC_IN[BLOCK LOC]=I8),FILTER(RC_IN[WT],RC_IN[BLOCK]=I9,RC_IN[BLOCK LOC]=I8))/SUM(FILTER(RC_IN[WT],RC_IN[BLOCK]=I9,RC_IN[BLOCK LOC]=I8)),"""") "),3.4160173905678755) -> 3.4160174 | J12: =IFERROR(__xludf.DUMMYFUNCTION("IFERROR(SUMPRODUCT(FILTER(RC_IN[ASH],RC_IN[BLOCK]=J9,RC_IN[BLOCK LOC]=J8),FILTER(RC_IN[WT],RC_IN[BLOCK]=J9,RC_IN[BLOCK LOC]=J8))/SUM(FILTER(RC_IN[WT],RC_IN[BLOCK]=J9,RC_IN[BLOCK LOC]=J8)),"""") "),3.543737753321702) -> 3.5437378 | K12: =IFERROR(__xludf.DUMMYFUNCTION("IFERROR(SUMPRODUCT(FILTER(RC_IN[ASH],RC_IN[BLOCK]=K9,RC_IN[BLOCK LOC]=K8),FILTER(RC_IN[WT],RC_IN[BLOCK]=K9,RC_IN[BLOCK LOC]=K8))/SUM(FILTER(RC_IN[WT],RC_IN[BLOCK]=K9,RC_IN[BLOCK LOC]=K8)),"""") "),3.644516649141255) -> 3.6445166 | L12: =IFERROR(__xludf.DUMMYFUNCTION("IFERROR(SUMPRODUCT(FILTER(RC_IN[ASH],RC_IN[BLOCK]=L9,RC_IN[BLOCK LOC]=L8),FILTER(RC_IN[WT],RC_IN[BLOCK]=L9,RC_IN[BLOCK LOC]=L8))/SUM(FILTER(RC_IN[WT],RC_IN[BLOCK]=L9,RC_IN[BLOCK LOC]=L8)),"""") "),3.5624911007189226) -> 3.5624911 | M12: =IFERROR(__xludf.DUMMYFUNCTION("IFERROR(SUMPRODUCT(FILTER(RC_IN[ASH],RC_IN[BLOCK]=M9,RC_IN[BLOCK LOC]=M8),FILTER(RC_IN[WT],RC_IN[BLOCK]=M9,RC_IN[BLOCK LOC]=M8))/SUM(FILTER(RC_IN[WT],RC_IN[BLOCK]=M9,RC_IN[BLOCK LOC]=M8)),"""") "),3.3543870601589107) -> 3.3543871 | N12: =IFERROR(__xludf.DUMMYFUNCTION("IFERROR(SUMPRODUCT(FILTER(RC_IN[ASH],RC_IN[BLOCK]=N9,RC_IN[BLOCK LOC]=N8),FILTER(RC_IN[WT],RC_IN[BLOCK]=N9,RC_IN[BLOCK LOC]=N8))/SUM(FILTER(RC_IN[WT],RC_IN[BLOCK]=N9,RC_IN[BLOCK LOC]=N8)),"""") "),3.2564002847735156) -> 3.2564003 | O12: =IFERROR(__xludf.DUMMYFUNCTION("IFERROR(SUMPRODUCT(FILTER(RC_IN[ASH],RC_IN[BLOCK]=O9,RC_IN[BLOCK LOC]=O8),FILTER(RC_IN[WT],RC_IN[BLOCK]=O9,RC_IN[BLOCK LOC]=O8))/SUM(FILTER(RC_IN[WT],RC_IN[BLOCK]=O9,RC_IN[BLOCK LOC]=O8)),"""") "),3.554622593718338) -> 3.5546226 | P12: =IFERROR(__xludf.DUMMYFUNCTION("IFERROR(SUMPRODUCT(FILTER(RC_IN[ASH],RC_IN[BLOCK]=P9,RC_IN[BLOCK LOC]=P8),FILTER(RC_IN[WT],RC_IN[BLOCK]=P9,RC_IN[BLOCK LOC]=P8))/SUM(FILTER(RC_IN[WT],RC_IN[BLOCK]=P9,RC_IN[BLOCK LOC]=P8)),"""") "),2.9181494083984227) -> 2.9181494 | Q12: =IFERROR(__xludf.DUMMYFUNCTION("IFERROR(SUMPRODUCT(FILTER(RC_IN[ASH],RC_IN[BLOCK]=Q9,RC_IN[BLOCK LOC]=Q8),FILTER(RC_IN[WT],RC_IN[BLOCK]=Q9,RC_IN[BLOCK LOC]=Q8))/SUM(FILTER(RC_IN[WT],RC_IN[BLOCK]=Q9,RC_IN[BLOCK LOC]=Q8)),"""") ")," ") | R12: =IFERROR(__xludf.DUMMYFUNCTION("IFERROR(SUMPRODUCT(FILTER(RC_IN[ASH],RC_IN[BLOCK]=R9,RC_IN[BLOCK LOC]=R8),FILTER(RC_IN[WT],RC_IN[BLOCK]=R9,RC_IN[BLOCK LOC]=R8))/SUM(FILTER(RC_IN[WT],RC_IN[BLOCK]=R9,RC_IN[BLOCK LOC]=R8)),"""") ")," ") | S12: =IFERROR(__xludf.DUMMYFUNCTION("IFERROR(SUMPRODUCT(FILTER(RC_IN[ASH],RC_IN[BLOCK]=S9,RC_IN[BLOCK LOC]=S8),FILTER(RC_IN[WT],RC_IN[BLOCK]=S9,RC_IN[BLOCK LOC]=S8))/SUM(FILTER(RC_IN[WT],RC_IN[BLOCK]=S9,RC_IN[BLOCK LOC]=S8)),"""") "),1.9207085226745804) -> 1.9207085 | T12: =IFERROR(__xludf.DUMMYFUNCTION("IFERROR(SUMPRODUCT(FILTER(RC_IN[ASH],RC_IN[BLOCK]=T9,RC_IN[BLOCK LOC]=T8),FILTER(RC_IN[WT],RC_IN[BLOCK]=T9,RC_IN[BLOCK LOC]=T8))/SUM(FILTER(RC_IN[WT],RC_IN[BLOCK]=T9,RC_IN[BLOCK LOC]=T8)),"""") "),2.85944275471023) -> 2.8594428 | U12: =IFERROR(__xludf.DUMMYFUNCTION("IFERROR(SUMPRODUCT(FILTER(RC_IN[ASH],RC_IN[BLOCK]=U9,RC_IN[BLOCK LOC]=U8),FILTER(RC_IN[WT],RC_IN[BLOCK]=U9,RC_IN[BLOCK LOC]=U8))/SUM(FILTER(RC_IN[WT],RC_IN[BLOCK]=U9,RC_IN[BLOCK LOC]=U8)),"""") "),2.81611733637856) -> 2.8161173 | V12: =IFERROR(__xludf.DUMMYFUNCTION("IFERROR(SUMPRODUCT(FILTER(RC_IN[ASH],RC_IN[BLOCK]=V9,RC_IN[BLOCK LOC]=V8),FILTER(RC_IN[WT],RC_IN[BLOCK]=V9,RC_IN[BLOCK LOC]=V8))/SUM(FILTER(RC_IN[WT],RC_IN[BLOCK]=V9,RC_IN[BLOCK LOC]=V8)),"""") "),2.845922543188898) -> 2.8459225 | W12: =IFERROR(__xludf.DUMMYFUNCTION("IFERROR(SUMPRODUCT(FILTER(RC_IN[ASH],RC_IN[BLOCK]=W9,RC_IN[BLOCK LOC]=W8),FILTER(RC_IN[WT],RC_IN[BLOCK]=W9,RC_IN[BLOCK LOC]=W8))/SUM(FILTER(RC_IN[WT],RC_IN[BLOCK]=W9,RC_IN[BLOCK LOC]=W8)),"""") ")," ") | X12: =IFERROR(__xludf.DUMMYFUNCTION("IFERROR(SUMPRODUCT(FILTER(RC_IN[ASH],RC_IN[BLOCK]=X9,RC_IN[BLOCK LOC]=X8),FILTER(RC_IN[WT],RC_IN[BLOCK]=X9,RC_IN[BLOCK LOC]=X8))/SUM(FILTER(RC_IN[WT],RC_IN[BLOCK]=X9,RC_IN[BLOCK LOC]=X8)),"""") "),3.4622018603543405) -> 3.4622019 | Y12: =IFERROR(__xludf.DUMMYFUNCTION("IFERROR(SUMPRODUCT(FILTER(RC_IN[ASH],RC_IN[BLOCK]=Y9,RC_IN[BLOCK LOC]=Y8),FILTER(RC_IN[WT],RC_IN[BLOCK]=Y9,RC_IN[BLOCK LOC]=Y8))/SUM(FILTER(RC_IN[WT],RC_IN[BLOCK]=Y9,RC_IN[BLOCK LOC]=Y8)),"""") "),3.0401311453359336) -> 3.0401311 | Z12: =IFERROR(__xludf.DUMMYFUNCTION("IFERROR(SUMPRODUCT(FILTER(RC_IN[ASH],RC_IN[BLOCK]=Z9,RC_IN[BLOCK LOC]=Z8),FILTER(RC_IN[WT],RC_IN[BLOCK]=Z9,RC_IN[BLOCK LOC]=Z8))/SUM(FILTER(RC_IN[WT],RC_IN[BLOCK]=Z9,RC_IN[BLOCK LOC]=Z8)),"""") "),3.8285043074884033) -> 3.8285043 | AA12: =IFERROR(__xludf.DUMMYFUNCTION("IFERROR(SUMPRODUCT(FILTER(RC_IN[ASH],RC_IN[BLOCK]=AA9,RC_IN[BLOCK LOC]=AA8),FILTER(RC_IN[WT],RC_IN[BLOCK]=AA9,RC_IN[BLOCK LOC]=AA8))/SUM(FILTER(RC_IN[WT],RC_IN[BLOCK]=AA9,RC_IN[BLOCK LOC]=AA8)),"""") "),3.35072792022792) -> 3.3507279 | AD12: ASH | AE12: =IFERROR(__xludf.DUMMYFUNCTION("IFERROR(SUMPRODUCT(FILTER(RC_IN[ASH],RC_IN[BLOCK]=AE9,RC_IN[BLOCK LOC]=AE8),FILTER(RC_IN[WT],RC_IN[BLOCK]=AE9,RC_IN[BLOCK LOC]=AE8))/SUM(FILTER(RC_IN[WT],RC_IN[BLOCK]=AE9,RC_IN[BLOCK LOC]=AE8)),"""") ")," ") | AF12: =IFERROR(__xludf.DUMMYFUNCTION("IFERROR(SUMPRODUCT(FILTER(RC_IN[ASH],RC_IN[BLOCK]=AF9,RC_IN[BLOCK LOC]=AF8),FILTER(RC_IN[WT],RC_IN[BLOCK]=AF9,RC_IN[BLOCK LOC]=AF8))/SUM(FILTER(RC_IN[WT],RC_IN[BLOCK]=AF9,RC_IN[BLOCK LOC]=AF8)),"""") ")," ") | AG12: =IFERROR(__xludf.DUMMYFUNCTION("IFERROR(SUMPRODUCT(FILTER(RC_IN[ASH],RC_IN[BLOCK]=AG9,RC_IN[BLOCK LOC]=AG8),FILTER(RC_IN[WT],RC_IN[BLOCK]=AG9,RC_IN[BLOCK LOC]=AG8))/SUM(FILTER(RC_IN[WT],RC_IN[BLOCK]=AG9,RC_IN[BLOCK LOC]=AG8)),"""") ")," ")
G13: MC | H13: =IFERROR(__xludf.DUMMYFUNCTION("IFERROR(SUMPRODUCT(FILTER(RC_IN[MC],RC_IN[BLOCK]=H9,RC_IN[BLOCK LOC]=H8),FILTER(RC_IN[WT],RC_IN[BLOCK]=H9,RC_IN[BLOCK LOC]=H8)) / SUM(FILTER(RC_IN[WT],RC_IN[BLOCK]=H9,RC_IN[BLOCK LOC]=H8)),"""") "),11.48674323101552) -> 11.486743 | I13: =IFERROR(__xludf.DUMMYFUNCTION("IFERROR(SUMPRODUCT(FILTER(RC_IN[MC],RC_IN[BLOCK]=I9,RC_IN[BLOCK LOC]=I8),FILTER(RC_IN[WT],RC_IN[BLOCK]=I9,RC_IN[BLOCK LOC]=I8)) / SUM(FILTER(RC_IN[WT],RC_IN[BLOCK]=I9,RC_IN[BLOCK LOC]=I8)),"""") "),11.401010967914967) -> 11.401011 | J13: =IFERROR(__xludf.DUMMYFUNCTION("IFERROR(SUMPRODUCT(FILTER(RC_IN[MC],RC_IN[BLOCK]=J9,RC_IN[BLOCK LOC]=J8),FILTER(RC_IN[WT],RC_IN[BLOCK]=J9,RC_IN[BLOCK LOC]=J8)) / SUM(FILTER(RC_IN[WT],RC_IN[BLOCK]=J9,RC_IN[BLOCK LOC]=J8)),"""") "),11.667843242517783) -> 11.667843 | K13: =IFERROR(__xludf.DUMMYFUNCTION("IFERROR(SUMPRODUCT(FILTER(RC_IN[MC],RC_IN[BLOCK]=K9,RC_IN[BLOCK LOC]=K8),FILTER(RC_IN[WT],RC_IN[BLOCK]=K9,RC_IN[BLOCK LOC]=K8)) / SUM(FILTER(RC_IN[WT],RC_IN[BLOCK]=K9,RC_IN[BLOCK LOC]=K8)),"""") "),11.64021310900806) -> 11.640213 | L13: =IFERROR(__xludf.DUMMYFUNCTION("IFERROR(SUMPRODUCT(FILTER(RC_IN[MC],RC_IN[BLOCK]=L9,RC_IN[BLOCK LOC]=L8),FILTER(RC_IN[WT],RC_IN[BLOCK]=L9,RC_IN[BLOCK LOC]=L8)) / SUM(FILTER(RC_IN[WT],RC_IN[BLOCK]=L9,RC_IN[BLOCK LOC]=L8)),"""") "),11.726696447267397) -> 11.726696 | M13: =IFERROR(__xludf.DUMMYFUNCTION("IFERROR(SUMPRODUCT(FILTER(RC_IN[MC],RC_IN[BLOCK]=M9,RC_IN[BLOCK LOC]=M8),FILTER(RC_IN[WT],RC_IN[BLOCK]=M9,RC_IN[BLOCK LOC]=M8)) / SUM(FILTER(RC_IN[WT],RC_IN[BLOCK]=M9,RC_IN[BLOCK LOC]=M8)),"""") "),10.330143776012108) -> 10.330144 | N13: =IFERROR(__xludf.DUMMYFUNCTION("IFERROR(SUMPRODUCT(FILTER(RC_IN[MC],RC_IN[BLOCK]=N9,RC_IN[BLOCK LOC]=N8),FILTER(RC_IN[WT],RC_IN[BLOCK]=N9,RC_IN[BLOCK LOC]=N8)) / SUM(FILTER(RC_IN[WT],RC_IN[BLOCK]=N9,RC_IN[BLOCK LOC]=N8)),"""") "),10.433435080537508) -> 10.433435 | O13: =IFERROR(__xludf.DUMMYFUNCTION("IFERROR(SUMPRODUCT(FILTER(RC_IN[MC],RC_IN[BLOCK]=O9,RC_IN[BLOCK LOC]=O8),FILTER(RC_IN[WT],RC_IN[BLOCK]=O9,RC_IN[BLOCK LOC]=O8)) / SUM(FILTER(RC_IN[WT],RC_IN[BLOCK]=O9,RC_IN[BLOCK LOC]=O8)),"""") "),11.14708037825059) -> 11.14708 | P13: =IFERROR(__xludf.DUMMYFUNCTION("IFERROR(SUMPRODUCT(FILTER(RC_IN[MC],RC_IN[BLOCK]=P9,RC_IN[BLOCK LOC]=P8),FILTER(RC_IN[WT],RC_IN[BLOCK]=P9,RC_IN[BLOCK LOC]=P8)) / SUM(FILTER(RC_IN[WT],RC_IN[BLOCK]=P9,RC_IN[BLOCK LOC]=P8)),"""") "),10.183730569948187) -> 10.183731 | Q13: =IFERROR(__xludf.DUMMYFUNCTION("IFERROR(SUMPRODUCT(FILTER(RC_IN[MC],RC_IN[BLOCK]=Q9,RC_IN[BLOCK LOC]=Q8),FILTER(RC_IN[WT],RC_IN[BLOCK]=Q9,RC_IN[BLOCK LOC]=Q8)) / SUM(FILTER(RC_IN[WT],RC_IN[BLOCK]=Q9,RC_IN[BLOCK LOC]=Q8)),"""") "),"") | R13: =IFERROR(__xludf.DUMMYFUNCTION("IFERROR(SUMPRODUCT(FILTER(RC_IN[MC],RC_IN[BLOCK]=R9,RC_IN[BLOCK LOC]=R8),FILTER(RC_IN[WT],RC_IN[BLOCK]=R9,RC_IN[BLOCK LOC]=R8)) / SUM(FILTER(RC_IN[WT],RC_IN[BLOCK]=R9,RC_IN[BLOCK LOC]=R8)),"""") "),"") | S13: =IFERROR(__xludf.DUMMYFUNCTION("IFERROR(SUMPRODUCT(FILTER(RC_IN[MC],RC_IN[BLOCK]=S9,RC_IN[BLOCK LOC]=S8),FILTER(RC_IN[WT],RC_IN[BLOCK]=S9,RC_IN[BLOCK LOC]=S8)) / SUM(FILTER(RC_IN[WT],RC_IN[BLOCK]=S9,RC_IN[BLOCK LOC]=S8)),"""") "),11.689831215802652) -> 11.689831 | T13: =IFERROR(__xludf.DUMMYFUNCTION("IFERROR(SUMPRODUCT(FILTER(RC_IN[MC],RC_IN[BLOCK]=T9,RC_IN[BLOCK LOC]=T8),FILTER(RC_IN[WT],RC_IN[BLOCK]=T9,RC_IN[BLOCK LOC]=T8)) / SUM(FILTER(RC_IN[WT],RC_IN[BLOCK]=T9,RC_IN[BLOCK LOC]=T8)),"""") "),12.13606639049834) -> 12.136066 | U13: =IFERROR(__xludf.DUMMYFUNCTION("IFERROR(SUMPRODUCT(FILTER(RC_IN[MC],RC_IN[BLOCK]=U9,RC_IN[BLOCK LOC]=U8),FILTER(RC_IN[WT],RC_IN[BLOCK]=U9,RC_IN[BLOCK LOC]=U8)) / SUM(FILTER(RC_IN[WT],RC_IN[BLOCK]=U9,RC_IN[BLOCK LOC]=U8)),"""") "),11.035553493683535) -> 11.035553 | V13: =IFERROR(__xludf.DUMMYFUNCTION("IFERROR(SUMPRODUCT(FILTER(RC_IN[MC],RC_IN[BLOCK]=V9,RC_IN[BLOCK LOC]=V8),FILTER(RC_IN[WT],RC_IN[BLOCK]=V9,RC_IN[BLOCK LOC]=V8)) / SUM(FILTER(RC_IN[WT],RC_IN[BLOCK]=V9,RC_IN[BLOCK LOC]=V8)),"""") "),11.328904701217786) -> 11.328905 | W13: =IFERROR(__xludf.DUMMYFUNCTION("IFERROR(SUMPRODUCT(FILTER(RC_IN[MC],RC_IN[BLOCK]=W9,RC_IN[BLOCK LOC]=W8),FILTER(RC_IN[WT],RC_IN[BLOCK]=W9,RC_IN[BLOCK LOC]=W8)) / SUM(FILTER(RC_IN[WT],RC_IN[BLOCK]=W9,RC_IN[BLOCK LOC]=W8)),"""") "),"") | X13: =IFERROR(__xludf.DUMMYFUNCTION("IFERROR(SUMPRODUCT(FILTER(RC_IN[MC],RC_IN[BLOCK]=X9,RC_IN[BLOCK LOC]=X8),FILTER(RC_IN[WT],RC_IN[BLOCK]=X9,RC_IN[BLOCK LOC]=X8)) / SUM(FILTER(RC_IN[WT],RC_IN[BLOCK]=X9,RC_IN[BLOCK LOC]=X8)),"""") "),10.677741905606204) -> 10.677742 | Y13: =IFERROR(__xludf.DUMMYFUNCTION("IFERROR(SUMPRODUCT(FILTER(RC_IN[MC],RC_IN[BLOCK]=Y9,RC_IN[BLOCK LOC]=Y8),FILTER(RC_IN[WT],RC_IN[BLOCK]=Y9,RC_IN[BLOCK LOC]=Y8)) / SUM(FILTER(RC_IN[WT],RC_IN[BLOCK]=Y9,RC_IN[BLOCK LOC]=Y8)),"""") "),11.596264039276347) -> 11.596264 | Z13: =IFERROR(__xludf.DUMMYFUNCTION("IFERROR(SUMPRODUCT(FILTER(RC_IN[MC],RC_IN[BLOCK]=Z9,RC_IN[BLOCK LOC]=Z8),FILTER(RC_IN[WT],RC_IN[BLOCK]=Z9,RC_IN[BLOCK LOC]=Z8)) / SUM(FILTER(RC_IN[WT],RC_IN[BLOCK]=Z9,RC_IN[BLOCK LOC]=Z8)),"""") "),11.428742213386348) -> 11.428742 | AA13: =IFERROR(__xludf.DUMMYFUNCTION("IFERROR(SUMPRODUCT(FILTER(RC_IN[MC],RC_IN[BLOCK]=AA9,RC_IN[BLOCK LOC]=AA8),FILTER(RC_IN[WT],RC_IN[BLOCK]=AA9,RC_IN[BLOCK LOC]=AA8)) / SUM(FILTER(RC_IN[WT],RC_IN[BLOCK]=AA9,RC_IN[BLOCK LOC]=AA8)),"""") "),10.782778490028491) -> 10.782778 | AD13: MC | AE13: =IFERROR(__xludf.DUMMYFUNCTION("IFERROR(SUMPRODUCT(FILTER(RC_IN[MC],RC_IN[BLOCK]=AE9,RC_IN[BLOCK LOC]=AE8),FILTER(RC_IN[WT],RC_IN[BLOCK]=AE9,RC_IN[BLOCK LOC]=AE8)) / SUM(FILTER(RC_IN[WT],RC_IN[BLOCK]=AE9,RC_IN[BLOCK LOC]=AE8)),"""") "),"") | AF13: =IFERROR(__xludf.DUMMYFUNCTION("IFERROR(SUMPRODUCT(FILTER(RC_IN[MC],RC_IN[BLOCK]=AF9,RC_IN[BLOCK LOC]=AF8),FILTER(RC_IN[WT],RC_IN[BLOCK]=AF9,RC_IN[BLOCK LOC]=AF8)) / SUM(FILTER(RC_IN[WT],RC_IN[BLOCK]=AF9,RC_IN[BLOCK LOC]=AF8)),"""") "),"") | AG13: =IFERROR(__xludf.DUMMYFUNCTION("IFERROR(SUMPRODUCT(FILTER(RC_IN[MC],RC_IN[BLOCK]=AG9,RC_IN[BLOCK LOC]=AG8),FILTER(RC_IN[WT],RC_IN[BLOCK]=AG9,RC_IN[BLOCK LOC]=AG8)) / SUM(FILTER(RC_IN[WT],RC_IN[BLOCK]=AG9,RC_IN[BLOCK LOC]=AG8)),"""") "),"")
D14: =D2 -> A | G14: C | H14: =CONCATENATE($D14,"-",H$1,$G14) -> A-1C | I14: =CONCATENATE($D14,"-",I$1,$G14) -> A-2C | J14: =CONCATENATE($D14,"-",J$1,$G14) -> A-3C | K14: =CONCATENATE($D14,"-",K$1,$G14) -> A-4C | L14: =CONCATENATE($D14,"-",L$1,$G14) -> A-5C | M14: =CONCATENATE($D14,"-",M$1,$G14) -> A-6C | N14: =CONCATENATE($D14,"-",N$1,$G14) -> A-7C | O14: =CONCATENATE($D14,"-",O$1,$G14) -> A-8C | ... AA14: =CONCATENATE($D14,"-",AA$1,$G14) -> A-20C | AC14: PCA | AD14: C | AE14: =CONCATENATE($AC14,"-",AE$1,$AD14) -> PCA-15C | AF14: =CONCATENATE($AC14,"-",AF$1,$AD14) -> PCA-16C | AG14: =CONCATENATE($AC14,"-",AG$1,$AD14) -> PCA-17C
