Workbook

Sheet EOQ Summary
A1: EOQ SUMMARY — Q3 2026
A3: CAMPAIGN | B3: RC FED (t) | C3: PRODUCED (t) | D3: YIELD | E3: LOSS | F3: WASTE (kg) | G3: WASTE % | H3: FED PRICE (₱/kg) | I3: ACTUAL FED PRICE (₱/kg) | J3: RESIKO COST (₱/kg) | K3: RESIKO LOSS | L3: PC COST (₱/kg) | M3: TRUE PC COST (₱/kg) | N3: fed kg in price set
A4: JULY 2026 | B4: ='JULY 2026'!B5 -> 781.234 | C4: ='JULY 2026'!C5 -> 621.201 | D4: ='JULY 2026'!D5 -> 0.79515356 | E4: ='JULY 2026'!E5 -> 0.20484644 | F4: ='JULY 2026'!F5 -> 106506.5 | G4: ='JULY 2026'!G5 -> 0.17145256 | H4: ='JULY 2026'!H5 -> 45.337719 | I4: ='JULY 2026'!I5 -> 47.577998 | ... L4: ='JULY 2026'!L5 -> 57.017564 | M4: =IF('JULY 2026'!M5="","",'JULY 2026'!M5) -> 59.83498 | N4: ='JULY 2026'!N5 -> 781234
A5: AUGUST 2026 | B5: ='AUGUST 2026'!B5 -> 697.313 | C5: ='AUGUST 2026'!C5 -> 553.376 | D5: ='AUGUST 2026'!D5 -> 0.79358337 | E5: ='AUGUST 2026'!E5 -> 0.20641663 | F5: ='AUGUST 2026'!F5 -> 78954.5 | G5: ='AUGUST 2026'!G5 -> 0.14267785 | H5: ='AUGUST 2026'!H5 -> 42.772035 | I5: ='AUGUST 2026'!I5 -> 43.939216 | ... L5: ='AUGUST 2026'!L5 -> 53.897343 | M5: =IF('AUGUST 2026'!M5="","",'AUGUST 2026'!M5) -> 55.368115 | N5: ='AUGUST 2026'!N5 -> 697313
A6: SEPTEMBER 2026 | B6: ='SEPTEMBER 2026'!B5 -> 500.744 | C6: ='SEPTEMBER 2026'!C5 -> 372.822 | D6: ='SEPTEMBER 2026'!D5 -> 0.74453613 | E6: ='SEPTEMBER 2026'!E5 -> 0.25546387 | F6: ='SEPTEMBER 2026'!F5 -> 59283.5 | G6: ='SEPTEMBER 2026'!G5 -> 0.15901288 | H6: ='SEPTEMBER 2026'!H5 -> 43.060268 | I6: ='SEPTEMBER 2026'!I5 -> 44.029833 | ... L6: ='SEPTEMBER 2026'!L5 -> 57.835028 | M6: =IF('SEPTEMBER 2026'!M5="","",'SEPTEMBER 2026'!M5) | N6: ='SEPTEMBER 2026'!N5 -> 362787
A7: GROUP · Q3 2026 | B7: =SUM(B4:B6) -> 1979.291 | C7: =SUM(C4:C6) -> 1547.399 | D7: =C7/B7 -> 0.78179459 | E7: =1-D7 -> 0.21820541 | F7: =SUM(F4:F6) -> 244744.5 | G7: =F7/(C7*1000) -> 0.15816509 | H7: =SUMPRODUCT(H4:H6,B4:B6)/SUM(B4:B6) -> 43.857641 | I7: =SUMPRODUCT(I4:I6,N4:N6)/SUM(N4:N6) -> 45.500918 | J7: =SUMPRODUCT(J4:J6,N4:N6)/SUM(N4:N6) -> 1.5103983 | K7: =SUMPRODUCT(K4:K6,N4:N6)/SUM(N4:N6) -> 0.032502634 | L7: =H7/D7 -> 56.098676 | M7: =IF(COUNTBLANK(M4:M6)=0,I7/D7,"") | N7: =SUM(N4:N6) -> 1841334
A9: CHECKS | B9: =IF(COUNTIF(Checks!F:F,"CHECK")=0,"All "&COUNTIF(Checks!F:F,"OK*")&" checks agree with the database",COUNTIF(Checks!F:F,"CHECK")&" of "&(COUNTIF(Checks!F:F,"OK*")+COUNTIF(Checks!F:F,"CHECK"))&" checks differ — see the Checks tab") -> All 39 checks agree with the database

Sheet JULY 2026
A1: JULY 2026 — PLANT OPERATIONS
A2: 2026-06-30 → 2026-08-01 · 33 days · 5 rest · blue = database value · black = formula · green = link to another tab
A4: EOM ROLLUP | B4: RC FED (t) | C4: PRODUCED (t) | D4: YIELD | E4: LOSS | F4: WASTE (kg) | G4: WASTE % | H4: FED PRICE (₱/kg) | I4: ACTUAL FED PRICE (₱/kg) | J4: RESIKO COST (₱/kg) | K4: RESIKO LOSS | L4: PC COST (₱/kg) | M4: TRUE PC COST (₱/kg) | N4: fed kg in price set
A5: JULY 2026 | B5: =D43/1000 -> 781.234 | C5: =E43/1000 -> 621.201 | D5: =E43/D43 -> 0.79515356 | E5: =1-D5 -> 0.20484644 | F5: =F43 -> 106506.5 | G5: =F43/E43 -> 0.17145256 | H5: =C43 -> 45.337719 | I5: =K67 -> 47.577998 | J5: =L67 -> 2.1714893 | K5: =I67 -> 0.044997601 | L5: =H5/D5 -> 57.017564 | M5: =IF(COUNTIF(M48:M66,"N")=0,I5/D5,"") -> 59.83498 | N5: =SUMPRODUCT((M48:M66="Y")*F48:F66) -> 781234
A8: DAY | C8: PRICE | D8: FED | E8: PRODUCED | F8: WASTE | H8: SHIFT | J8: GRADES | O8: WASTE STREAMS
A9: DATE | B9: DAY | C9: FED PRICE ₱/kg | D9: TTL FED kg | E9: TTL PROD kg | F9: WASTE kg | G9: WASTE % | H9: SHIFTS | I9: DT HRS | J9: 3X50 kg | K9: 6X50 kg | L9: 8X50 kg | M9: 2X6 kg | N9: 4X8 kg | O9: TRML 1 kg | P9: TRML 2 kg | Q9: RS1A kg | R9: RS1B kg | S9: RS2/3 kg | T9: RS5 kg | U9: BF kg | V9: GRITS kg
A10: 46203 | B10: Tue | C10: 44.0221 | D10: ='RC Movement'!E7 -> 18963 | E10: =SUM(J10:N10) -> 7760 | F10: =SUM(O10:V10) -> 2145.5 | G10: =IF(E10>0,F10/E10,"") -> 0.27648196 | H10: 1 | I10: 0 | J10: 5460 | N10: 2300 | O10: 50 | P10: 0.5 | Q10: 1038 | R10: 784 | S10: 137 | T10: 71 | U10: 35 | V10: 30
A11: 46204 | B11: Wed | C11: 42.7426 | D11: ='RC Movement'!E8 -> 36226 | E11: =SUM(J11:N11) -> 30098 | F11: =SUM(O11:V11) -> 6152.5 | G11: =IF(E11>0,F11/E11,"") -> 0.20441558 | H11: 1 | I11: 0.17 | J11: 22048 | N11: 8050 | O11: 100 | P11: 0.5 | Q11: 2370 | R11: 2486 | S11: 607 | T11: 226 | U11: 315 | V11: 48
A12: 46205 | B12: Thu | C12: 43.3234 | D12: ='RC Movement'!E9 -> 30992 | E12: =SUM(J12:N12) -> 30852 | F12: =SUM(O12:V12) -> 4674.5 | G12: =IF(E12>0,F12/E12,"") -> 0.15151368 | H12: 1 | I12: 0.17 | J12: 22802 | N12: 8050 | O12: 125 | P12: 0.5 | Q12: 1545 | R12: 1587 | S12: 736 | T12: 347 | U12: 275 | V12: 59
A13: 46206 | B13: Fri | C13: 44.246 | D13: ='RC Movement'!E10 -> 33040 | E13: =SUM(J13:N13) -> 26377 | F13: =SUM(O13:V13) -> 5130.5 | G13: =IF(E13>0,F13/E13,"") -> 0.19450658 | H13: 1 | I13: 1.67 | J13: 18902 | N13: 7475 | O13: 132 | P13: 0.5 | Q13: 2080 | R13: 1696 | S13: 622 | T13: 212 | U13: 330 | V13: 58
A14: 46207 | B14: Sat | C14: 44.6338 | D14: ='RC Movement'!E11 -> 35066 | E14: =SUM(J14:N14) -> 28411 | F14: =SUM(O14:V14) -> 5471.5 | G14: =IF(E14>0,F14/E14,"") -> 0.19258386 | H14: 1 | I14: 1.28 | J14: 19786 | N14: 8625 | O14: 200 | P14: 0.5 | Q14: 2080 | R14: 1988 | S14: 635 | T14: 239 | U14: 285 | V14: 44
A15: 46208 | B15: Sun | D15: ='RC Movement'!E12 -> 0 | E15: =SUM(J15:N15) -> 0 | F15: =SUM(O15:V15) -> 0 | G15: =IF(E15>0,F15/E15,"")
A16: 46209 | B16: Mon | C16: 45.2625 | D16: ='RC Movement'!E13 -> 33892 | E16: =SUM(J16:N16) -> 28278 | F16: =SUM(O16:V16) -> 4264.5 | G16: =IF(E16>0,F16/E16,"") -> 0.15080628 | H16: 1 | I16: 0.12 | J16: 20228 | N16: 8050 | O16: 125 | P16: 0.5 | Q16: 1547 | R16: 1540 | S16: 586 | T16: 247 | U16: 175 | V16: 44
A17: 46210 | B17: Tue | C17: 45.4369 | D17: ='RC Movement'!E14 -> 32944 | E17: =SUM(J17:N17) -> 27151 | F17: =SUM(O17:V17) -> 4488.5 | G17: =IF(E17>0,F17/E17,"") -> 0.16531619 | H17: 1 | I17: 0.2 | J17: 20826 | N17: 6325 | O17: 136 | P17: 0.5 | Q17: 1564 | R17: 1662 | S17: 582 | T17: 273 | U17: 216 | V17: 55
A18: 46211 | B18: Wed | C18: 44.6154 | D18: ='RC Movement'!E15 -> 36171 | E18: =SUM(J18:N18) -> 26738 | F18: =SUM(O18:V18) -> 5008.5 | G18: =IF(E18>0,F18/E18,"") -> 0.18731768 | H18: 1 | I18: 2.42 | J18: 19838 | N18: 6900 | O18: 175 | P18: 0.5 | Q18: 2080 | R18: 1699 | S18: 578 | T18: 144 | U18: 275 | V18: 57
A19: 46212 | B19: Thu | C19: 41.1244 | D19: ='RC Movement'!E16 -> 38644 | E19: =SUM(J19:N19) -> 29676 | F19: =SUM(O19:V19) -> 4883.5 | G19: =IF(E19>0,F19/E19,"") -> 0.16456059 | H19: 1 | I19: 0.25 | J19: 22776 | N19: 6900 | O19: 161 | P19: 0.5 | Q19: 2080 | R19: 1655 | S19: 557 | T19: 218 | U19: 151 | V19: 61
A20: 46213 | B20: Fri | C20: 45.7043 | D20: ='RC Movement'!E17 -> 36541 | E20: =SUM(J20:N20) -> 29711 | F20: =SUM(O20:V20) -> 5497.5 | G20: =IF(E20>0,F20/E20,"") -> 0.18503248 | H20: 1 | I20: 0.65 | J20: 21086 | N20: 8625 | O20: 250 | P20: 0.5 | Q20: 2080 | R20: 2057 | S20: 759 | T20: 145 | U20: 150 | V20: 56
A21: 46214 | B21: Sat | C21: 45.2004 | D21: ='RC Movement'!E18 -> 37409 | E21: =SUM(J21:N21) -> 28301 | F21: =SUM(O21:V21) -> 5146.5 | G21: =IF(E21>0,F21/E21,"") -> 0.1818487 | H21: 1 | I21: 0.17 | J21: 20826 | N21: 7475 | O21: 125 | P21: 0.5 | Q21: 2080 | R21: 1661 | S21: 768 | T21: 237 | U21: 215 | V21: 60
A22: 46215 | B22: Sun | D22: ='RC Movement'!E19 -> 0 | E22: =SUM(J22:N22) -> 0 | F22: =SUM(O22:V22) -> 0 | G22: =IF(E22>0,F22/E22,"")
A23: 46216 | B23: Mon | C23: 48.4234 | D23: ='RC Movement'!E20 -> 25492 | E23: =SUM(J23:N23) -> 15730 | F23: =SUM(O23:V23) -> 2670.5 | G23: =IF(E23>0,F23/E23,"") -> 0.16977114 | H23: 1 | I23: 2.05 | J23: 15730 | O23: 50 | P23: 0.5 | Q23: 1040 | R23: 1040 | S23: 180 | T23: 120 | U23: 210 | V23: 30
A24: 46217 | B24: Tue | C24: 48.1897 | D24: ='RC Movement'!E21 -> 42356 | E24: =SUM(J24:N24) -> 19136 | F24: =SUM(O24:V24) -> 2634.5 | G24: =IF(E24>0,F24/E24,"") -> 0.13767245 | H24: 1 | I24: 0.08 | J24: 19136 | O24: 75 | P24: 0.5 | Q24: 1040 | R24: 1040 | S24: 108 | T24: 193 | U24: 150 | V24: 28
A25: 46218 | B25: Wed | C25: 48.2329 | D25: ='RC Movement'!E22 -> 10366 | E25: =SUM(J25:N25) -> 15340 | F25: =SUM(O25:V25) -> 4076.5 | G25: =IF(E25>0,F25/E25,"") -> 0.26574316 | H25: 1 | I25: 1.33 | J25: 15340 | O25: 50 | P25: 0.5 | Q25: 1687 | R25: 1847 | S25: 95 | T25: 157 | U25: 210 | V25: 30
A26: 46219 | B26: Thu | C26: 48.1946 | D26: ='RC Movement'!E23 -> 19966 | E26: =SUM(J26:N26) -> 16562 | F26: =SUM(O26:V26) -> 2595.5 | G26: =IF(E26>0,F26/E26,"") -> 0.15671416 | H26: 1 | I26: 0.1 | J26: 16562 | O26: 75 | P26: 0.5 | Q26: 1040 | R26: 1040 | S26: 119 | T26: 162 | U26: 130 | V26: 29
A27: 46220 | B27: Fri | D27: ='RC Movement'!E24 -> 0 | E27: =SUM(J27:N27) -> 0 | F27: =SUM(O27:V27) -> 0 | G27: =IF(E27>0,F27/E27,"") | H27: 1 | I27: 0
A28: 46221 | B28: Sat | D28: ='RC Movement'!E25 -> 0 | E28: =SUM(J28:N28) -> 0 | F28: =SUM(O28:V28) -> 0 | G28: =IF(E28>0,F28/E28,"")
A29: 46222 | B29: Sun | D29: ='RC Movement'!E26 -> 0 | E29: =SUM(J29:N29) -> 0 | F29: =SUM(O29:V29) -> 0 | G29: =IF(E29>0,F29/E29,"")
A30: 46223 | B30: Mon | C30: 45.4203 | D30: ='RC Movement'!E27 -> 22126 | E30: =SUM(J30:N30) -> 19318 | F30: =SUM(O30:V30) -> 2558.5 | G30: =IF(E30>0,F30/E30,"") -> 0.13244125 | H30: 1 | I30: 1.75 | J30: 19318 | O30: 50 | P30: 0.5 | Q30: 1040 | R30: 1040 | S30: 138 | T30: 140 | U30: 120 | V30: 30
A31: 46224 | B31: Tue | C31: 41.962 | D31: ='RC Movement'!E28 -> 31699 | E31: =SUM(J31:N31) -> 20358 | F31: =SUM(O31:V31) -> 2422.5 | G31: =IF(E31>0,F31/E31,"") -> 0.11899499 | H31: 1 | I31: 1.47 | J31: 20358 | O31: 75 | P31: 0.5 | Q31: 1040 | R31: 1040 | S31: 54 | T31: 75 | U31: 110 | V31: 28
A32: 46225 | B32: Wed | C32: 44.3621 | D32: ='RC Movement'!E29 -> 40763 | E32: =SUM(J32:N32) -> 31312 | F32: =SUM(O32:V32) -> 3580.5 | G32: =IF(E32>0,F32/E32,"") -> 0.11434913 | H32: 1 | I32: 0.33 | J32: 18772 | M32: 12540 | O32: 75 | P32: 0.5 | Q32: 1474 | R32: 1515 | S32: 77 | T32: 177 | U32: 205 | V32: 57
A33: 46226 | B33: Thu | C33: 46.7782 | D33: ='RC Movement'!E30 -> 42142 | E33: =SUM(J33:N33) -> 28500 | F33: =SUM(O33:V33) -> 5545.5 | G33: =IF(E33>0,F33/E33,"") -> 0.19457895 | H33: 1 | I33: 0.87 | J33: 14820 | M33: 13680 | O33: 105 | P33: 0.5 | Q33: 2080 | R33: 2766 | S33: 107 | T33: 207 | U33: 225 | V33: 55
A34: 46227 | B34: Fri | C34: 46.2208 | D34: ='RC Movement'!E31 -> 41500 | E34: =SUM(J34:N34) -> 30362 | F34: =SUM(O34:V34) -> 5746.5 | G34: =IF(E34>0,F34/E34,"") -> 0.18926619 | H34: 1 | I34: 0.2 | J34: 13832 | M34: 16530 | O34: 125 | P34: 0.5 | Q34: 2080 | R34: 2906 | S34: 103 | T34: 221 | U34: 255 | V34: 56
A35: 46228 | B35: Sat | C35: 45.6054 | D35: ='RC Movement'!E32 -> 31019 | E35: =SUM(J35:N35) -> 30336 | F35: =SUM(O35:V35) -> 4444.5 | G35: =IF(E35>0,F35/E35,"") -> 0.1465091 | H35: 1 | I35: 0.75 | J35: 13806 | M35: 16530 | O35: 75 | P35: 0.5 | Q35: 2080 | R35: 1745 | S35: 85 | T35: 176 | U35: 225 | V35: 58
A36: 46229 | B36: Sun | D36: ='RC Movement'!E33 -> 0 | E36: =SUM(J36:N36) -> 0 | F36: =SUM(O36:V36) -> 0 | G36: =IF(E36>0,F36/E36,"")
A37: 46230 | B37: Mon | C37: 46.5932 | D37: ='RC Movement'!E34 -> 42584 | E37: =SUM(J37:N37) -> 24600 | F37: =SUM(O37:V37) -> 2211.5 | G37: =IF(E37>0,F37/E37,"") -> 0.089898374 | H37: 1 | I37: 0.17 | J37: 10920 | M37: 13680 | O37: 50 | P37: 0.5 | Q37: 910 | R37: 820 | S37: 96 | T37: 135 | U37: 150 | V37: 50
A38: 46231 | B38: Tue | C38: 46.4774 | D38: ='RC Movement'!E35 -> 30499 | E38: =SUM(J38:N38) -> 25068 | F38: =SUM(O38:V38) -> 4732.5 | G38: =IF(E38>0,F38/E38,"") -> 0.1887865 | H38: 1 | I38: 0.17 | J38: 11388 | M38: 13680 | O38: 75 | P38: 0.5 | Q38: 2080 | R38: 2174 | S38: 83 | T38: 117 | U38: 175 | V38: 28
A39: 46232 | B39: Wed | C39: 48.1486 | D39: ='RC Movement'!E36 -> 30834 | E39: =SUM(J39:N39) -> 21278 | F39: =SUM(O39:V39) -> 4315.5 | G39: =IF(E39>0,F39/E39,"") -> 0.20281511 | H39: 1 | I39: 0.83 | J39: 16718 | M39: 4560 | O39: 57 | P39: 0.5 | Q39: 2080 | R39: 1593 | S39: 160 | T39: 173 | U39: 225 | V39: 27
A40: 46233 | B40: Thu | D40: ='RC Movement'!E37 -> 0 | E40: =SUM(J40:N40) -> 22862 | F40: =SUM(O40:V40) -> 4318.5 | G40: =IF(E40>0,F40/E40,"") -> 0.18889423 | H40: 1 | I40: 0.17 | J40: 10322 | M40: 12540 | O40: 75 | P40: 0.5 | Q40: 2080 | R40: 1745 | S40: 80 | T40: 158 | U40: 150 | V40: 30
A41: 46234 | B41: Fri | D41: ='RC Movement'!E38 -> 0 | E41: =SUM(J41:N41) -> 4620 | F41: =SUM(O41:V41) -> 1199.5 | G41: =IF(E41>0,F41/E41,"") -> 0.25963203 | H41: 1 | I41: 4.97 | J41: 2340 | M41: 2280 | O41: 30 | P41: 0.5 | Q41: 550 | R41: 410 | S41: 50 | T41: 56 | U41: 75 | V41: 28
A42: 46235 | B42: Sat | D42: ='RC Movement'!E39 -> 0 | E42: =SUM(J42:N42) -> 2466 | F42: =SUM(O42:V42) -> 590.5 | G42: =IF(E42>0,F42/E42,"") -> 0.23945661 | H42: 1 | I42: 0.22 | J42: 1326 | M42: 1140 | O42: 25 | P42: 0.5 | Q42: 239 | R42: 239 | S42: 27 | T42: 35 | U42: 0 | V42: 25
A43: JULY 2026 | B43: 33 d | C43: =SUMPRODUCT(C10:C42,D10:D42)/SUMIF(C10:C42,">0",D10:D42) -> 45.337719 | D43: =SUM(D10:D42) -> 781234 | E43: =SUM(E10:E42) -> 621201 | F43: =SUM(F10:F42) -> 106506.5 | G43: =IF(E43>0,F43/E43,"") -> 0.17145256 | H43: =SUM(H10:H42) -> 28 | I43: =SUM(I10:I42) -> 22.56 | J43: =SUM(J10:J42) -> 435266 | K43: =SUM(K10:K42) -> 0 | L43: =SUM(L10:L42) -> 0 | M43: =SUM(M10:M42) -> 107160 | N43: =SUM(N10:N42) -> 78775 | O43: =SUM(O10:O42) -> 2646 | ... V43: =SUM(V10:V42) -> 1161
...

Sheet AUGUST 2026
A1: AUGUST 2026 — PLANT OPERATIONS
A2: 2026-08-01 → 2026-08-29 · 29 days · 6 rest · blue = database value · black = formula · green = link to another tab
A4: EOM ROLLUP | B4: RC FED (t) | C4: PRODUCED (t) | D4: YIELD | E4: LOSS | F4: WASTE (kg) | G4: WASTE % | H4: FED PRICE (₱/kg) | I4: ACTUAL FED PRICE (₱/kg) | J4: RESIKO COST (₱/kg) | K4: RESIKO LOSS | L4: PC COST (₱/kg) | M4: TRUE PC COST (₱/kg) | N4: fed kg in price set
A5: AUGUST 2026 | B5: =D39/1000 -> 697.313 | C5: =E39/1000 -> 553.376 | D5: =E39/D39 -> 0.79358337 | E5: =1-D5 -> 0.20641663 | F5: =F39 -> 78954.5 | G5: =F39/E39 -> 0.14267785 | H5: =C39 -> 42.772035 | I5: =K64 -> 43.939216 | J5: =L64 -> 1.0842165 | K5: =I64 -> 0.024606567 | L5: =H5/D5 -> 53.897343 | M5: =IF(COUNTIF(M44:M63,"N")=0,I5/D5,"") -> 55.368115 | N5: =SUMPRODUCT((M44:M63="Y")*F44:F63) -> 697313
A8: DAY | C8: PRICE | D8: FED | E8: PRODUCED | F8: WASTE | H8: SHIFT | J8: GRADES | O8: WASTE STREAMS
A9: DATE | B9: DAY | C9: FED PRICE ₱/kg | D9: TTL FED kg | E9: TTL PROD kg | F9: WASTE kg | G9: WASTE % | H9: SHIFTS | I9: DT HRS | J9: 3X50 kg | K9: 6X50 kg | L9: 8X50 kg | M9: 2X6 kg | N9: 4X8 kg | O9: TRML 1 kg | P9: TRML 2 kg | Q9: RS1A kg | R9: RS1B kg | S9: RS2/3 kg | T9: RS5 kg | U9: BF kg | V9: GRITS kg
A10: 46235 | B10: Sat | C10: 48.5774 | D10: ='RC Movement'!E49 -> 30326 | E10: =SUM(J10:N10) -> 11830 | F10: =SUM(O10:V10) -> 993.5 | G10: =IF(E10>0,F10/E10,"") -> 0.083981403 | H10: 1 | I10: 0 | J10: 11830 | O10: 50 | P10: 0.5 | Q10: 520 | R10: 0 | S10: 90 | T10: 94 | U10: 210 | V10: 29
A11: 46236 | B11: Sun | D11: ='RC Movement'!E50 -> 0 | E11: =SUM(J11:N11) -> 0 | F11: =SUM(O11:V11) -> 0 | G11: =IF(E11>0,F11/E11,"")
A12: 46237 | B12: Mon | C12: 48.7898 | D12: ='RC Movement'!E51 -> 32421 | E12: =SUM(J12:N12) -> 23608 | F12: =SUM(O12:V12) -> 3414.5 | G12: =IF(E12>0,F12/E12,"") -> 0.14463318 | H12: 1 | I12: 0.28 | J12: 23608 | O12: 50 | P12: 0.5 | Q12: 1650 | R12: 1134 | S12: 197 | T12: 183 | U12: 170 | V12: 30
A13: 46238 | B13: Tue | C13: 48.7881 | D13: ='RC Movement'!E52 -> 32242 | E13: =SUM(J13:N13) -> 24700 | F13: =SUM(O13:V13) -> 4185.5 | G13: =IF(E13>0,F13/E13,"") -> 0.16945344 | H13: 1 | I13: 0.08 | J13: 24700 | O13: 75 | P13: 0.5 | Q13: 1650 | R13: 1897 | S13: 199 | T13: 186 | U13: 150 | V13: 28
A14: 46239 | B14: Wed | C14: 46.0675 | D14: ='RC Movement'!E53 -> 37085 | E14: =SUM(J14:N14) -> 25168 | F14: =SUM(O14:V14) -> 3414.5 | G14: =IF(E14>0,F14/E14,"") -> 0.13566831 | H14: 1 | I14: 0.52 | J14: 25168 | O14: 50 | P14: 0.5 | Q14: 1650 | R14: 1247 | S14: 168 | T14: 148 | U14: 125 | V14: 26
A15: 46240 | B15: Thu | C15: 40.6858 | D15: ='RC Movement'!E54 -> 38998 | E15: =SUM(J15:N15) -> 26520 | F15: =SUM(O15:V15) -> 3361.5 | G15: =IF(E15>0,F15/E15,"") -> 0.12675339 | H15: 1 | I15: 0.13 | J15: 26520 | O15: 100 | P15: 0.5 | Q15: 1650 | R15: 1214 | S15: 157 | T15: 135 | U15: 75 | V15: 30
A16: 46241 | B16: Fri | C16: 39.093 | D16: ='RC Movement'!E55 -> 26525 | E16: =SUM(J16:N16) -> 22620 | F16: =SUM(O16:V16) -> 2691.5 | G16: =IF(E16>0,F16/E16,"") -> 0.11898762 | H16: 1 | I16: 2.2 | J16: 22620 | O16: 50 | P16: 0.5 | Q16: 1100 | R16: 1206 | S16: 129 | T16: 77 | U16: 100 | V16: 29
A17: 46242 | B17: Sat | C17: 38.8398 | D17: ='RC Movement'!E56 -> 36105 | E17: =SUM(J17:N17) -> 28600 | F17: =SUM(O17:V17) -> 3409.5 | G17: =IF(E17>0,F17/E17,"") -> 0.11921329 | H17: 1 | I17: 0.08 | J17: 28600 | O17: 75 | P17: 0.5 | Q17: 1650 | R17: 1300 | S17: 214 | T17: 92 | U17: 50 | V17: 28
A18: 46243 | B18: Sun | D18: ='RC Movement'!E57 -> 0 | E18: =SUM(J18:N18) -> 0 | F18: =SUM(O18:V18) -> 0 | G18: =IF(E18>0,F18/E18,"")
A19: 46244 | B19: Mon | C19: 39.2725 | D19: ='RC Movement'!E58 -> 28492 | E19: =SUM(J19:N19) -> 27040 | F19: =SUM(O19:V19) -> 2941.5 | G19: =IF(E19>0,F19/E19,"") -> 0.10878328 | H19: 1 | I19: 3 | J19: 27040 | O19: 25 | P19: 0.5 | Q19: 1650 | R19: 961 | S19: 162 | T19: 63 | U19: 50 | V19: 30
A20: 46245 | B20: Tue | C20: 39.6142 | D20: ='RC Movement'!E59 -> 35359 | E20: =SUM(J20:N20) -> 26390 | F20: =SUM(O20:V20) -> 2659.5 | G20: =IF(E20>0,F20/E20,"") -> 0.10077681 | H20: 1 | I20: 0 | J20: 26390 | O20: 75 | P20: 0.5 | Q20: 1100 | R20: 1100 | S20: 194 | T20: 87 | U20: 75 | V20: 28
A21: 46246 | B21: Wed | C21: 44.7178 | D21: ='RC Movement'!E60 -> 32228 | E21: =SUM(J21:N21) -> 25012 | F21: =SUM(O21:V21) -> 3549.5 | G21: =IF(E21>0,F21/E21,"") -> 0.14191188 | H21: 1 | I21: 0.47 | J21: 25012 | O21: 50 | P21: 0.5 | Q21: 1650 | R21: 1243 | S21: 459 | T21: 68 | U21: 50 | V21: 29
A22: 46247 | B22: Thu | C22: 46.2764 | D22: ='RC Movement'!E61 -> 20068 | E22: =SUM(J22:N22) -> 23400 | F22: =SUM(O22:V22) -> 3468.5 | G22: =IF(E22>0,F22/E22,"") -> 0.1482265 | H22: 1 | I22: 0.17 | J22: 23400 | O22: 100 | P22: 0.5 | Q22: 1650 | R22: 1194 | S22: 331 | T22: 88 | U22: 75 | V22: 30
A23: 46248 | B23: Fri | C23: 46.5818 | D23: ='RC Movement'!E62 -> 17565 | E23: =SUM(J23:N23) -> 23530 | F23: =SUM(O23:V23) -> 4779.5 | G23: =IF(E23>0,F23/E23,"") -> 0.20312367 | H23: 1 | I23: 0.13 | J23: 23530 | O23: 75 | P23: 0.5 | Q23: 2200 | R23: 1854 | S23: 374 | T23: 123 | U23: 125 | V23: 28
A24: 46249 | B24: Sat | D24: ='RC Movement'!E63 -> 0 | E24: =SUM(J24:N24) -> 0 | F24: =SUM(O24:V24) -> 0 | G24: =IF(E24>0,F24/E24,"")
A25: 46250 | B25: Sun | D25: ='RC Movement'!E64 -> 0 | E25: =SUM(J25:N25) -> 0 | F25: =SUM(O25:V25) -> 0 | G25: =IF(E25>0,F25/E25,"")
A26: 46251 | B26: Mon | C26: 44.2478 | D26: ='RC Movement'!E65 -> 34120 | E26: =SUM(J26:N26) -> 22932 | F26: =SUM(O26:V26) -> 3364.5 | G26: =IF(E26>0,F26/E26,"") -> 0.14671638 | H26: 1 | I26: 0.32 | J26: 22932 | O26: 55 | P26: 0.5 | Q26: 1650 | R26: 1089 | S26: 272 | T26: 93 | U26: 175 | V26: 30
A27: 46252 | B27: Tue | C27: 39.8626 | D27: ='RC Movement'!E66 -> 33549 | E27: =SUM(J27:N27) -> 24388 | F27: =SUM(O27:V27) -> 4000.5 | G27: =IF(E27>0,F27/E27,"") -> 0.16403559 | H27: 1 | I27: 1.12 | J27: 24388 | O27: 75 | P27: 0.5 | Q27: 1650 | R27: 1838 | S27: 175 | T27: 134 | U27: 100 | V27: 28
A28: 46253 | B28: Wed | C28: 42.6566 | D28: ='RC Movement'!E67 -> 33960 | E28: =SUM(J28:N28) -> 26234 | F28: =SUM(O28:V28) -> 4085.5 | G28: =IF(E28>0,F28/E28,"") -> 0.15573302 | H28: 1 | I28: 0.97 | J28: 26234 | O28: 50 | P28: 0.5 | Q28: 1650 | R28: 1889 | S28: 214 | T28: 178 | U28: 75 | V28: 29
A29: 46254 | B29: Thu | C29: 42.3629 | D29: ='RC Movement'!E68 -> 38270 | E29: =SUM(J29:N29) -> 28340 | F29: =SUM(O29:V29) -> 3252.5 | G29: =IF(E29>0,F29/E29,"") -> 0.11476711 | H29: 1 | I29: 0.3 | J29: 28340 | O29: 75 | P29: 0.5 | Q29: 1650 | R29: 1050 | S29: 235 | T29: 137 | U29: 75 | V29: 30
A30: 46255 | B30: Fri | C30: 42.1848 | D30: ='RC Movement'!E69 -> 32261 | E30: =SUM(J30:N30) -> 25480 | F30: =SUM(O30:V30) -> 3961.5 | G30: =IF(E30>0,F30/E30,"") -> 0.15547488 | H30: 1 | I30: 1.1 | J30: 25480 | O30: 100 | P30: 0.5 | Q30: 1650 | R30: 1829 | S30: 172 | T30: 132 | U30: 50 | V30: 28
A31: 46256 | B31: Sat | D31: ='RC Movement'!E70 -> 0 | E31: =SUM(J31:N31) -> 0 | F31: =SUM(O31:V31) -> 0 | G31: =IF(E31>0,F31/E31,"")
A32: 46257 | B32: Sun | D32: ='RC Movement'!E71 -> 0 | E32: =SUM(J32:N32) -> 0 | F32: =SUM(O32:V32) -> 0 | G32: =IF(E32>0,F32/E32,"")
A33: 46258 | B33: Mon | C33: 42.7871 | D33: ='RC Movement'!E72 -> 43603 | E33: =SUM(J33:N33) -> 24644 | F33: =SUM(O33:V33) -> 4711.5 | G33: =IF(E33>0,F33/E33,"") -> 0.19118244 | H33: 1 | I33: 0.85 | J33: 16094 | K33: 8550 | O33: 75 | P33: 0.5 | Q33: 1650 | R33: 2043 | S33: 648 | T33: 191 | U33: 75 | V33: 29
A34: 46259 | B34: Tue | C34: 39.0616 | D34: ='RC Movement'!E73 -> 33665 | E34: =SUM(J34:N34) -> 27420 | F34: =SUM(O34:V34) -> 3816.5 | G34: =IF(E34>0,F34/E34,"") -> 0.13918673 | H34: 1 | I34: 0.57 | J34: 17160 | K34: 10260 | O34: 100 | P34: 0.5 | Q34: 1650 | R34: 1176 | S34: 569 | T34: 194 | U34: 100 | V34: 27
A35: 46260 | B35: Wed | C35: 40.9001 | D35: ='RC Movement'!E74 -> 35094 | E35: =SUM(J35:N35) -> 25262 | F35: =SUM(O35:V35) -> 4170.5 | G35: =IF(E35>0,F35/E35,"") -> 0.16508986 | H35: 1 | I35: 0.65 | J35: 15002 | K35: 10260 | O35: 75 | P35: 0.5 | Q35: 1650 | R35: 1612 | S35: 510 | T35: 168 | U35: 125 | V35: 30
A36: 46261 | B36: Thu | C36: 40.8118 | D36: ='RC Movement'!E75 -> 28213 | E36: =SUM(J36:N36) -> 26820 | F36: =SUM(O36:V36) -> 3387.5 | G36: =IF(E36>0,F36/E36,"") -> 0.126305 | H36: 1 | I36: 0.23 | J36: 15990 | K36: 10830 | O36: 120 | P36: 0.5 | Q36: 1650 | R36: 1075 | S36: 263 | T36: 141 | U36: 110 | V36: 28
A37: 46262 | B37: Fri | C37: 41.3753 | D37: ='RC Movement'!E76 -> 17164 | E37: =SUM(J37:N37) -> 25390 | F37: =SUM(O37:V37) -> 3825.5 | G37: =IF(E37>0,F37/E37,"") -> 0.15066955 | H37: 1 | I37: 0.25 | J37: 14560 | K37: 10830 | O37: 125 | P37: 0.5 | Q37: 1650 | R37: 1077 | S37: 668 | T37: 150 | U37: 125 | V37: 30
A38: 46263 | B38: Sat | D38: ='RC Movement'!E77 -> 0 | E38: =SUM(J38:N38) -> 8048 | F38: =SUM(O38:V38) -> 1509.5 | G38: =IF(E38>0,F38/E38,"") -> 0.18756213 | H38: 1 | I38: 0.18 | J38: 4628 | K38: 3420 | O38: 50 | P38: 0.5 | Q38: 550 | R38: 550 | S38: 196 | T38: 97 | U38: 50 | V38: 16
A39: AUGUST 2026 | B39: 29 d | C39: =SUMPRODUCT(C10:C38,D10:D38)/SUMIF(C10:C38,">0",D10:D38) -> 42.772035 | D39: =SUM(D10:D38) -> 697313 | E39: =SUM(E10:E38) -> 553376 | F39: =SUM(F10:F38) -> 78954.5 | G39: =IF(E39>0,F39/E39,"") -> 0.14267785 | H39: =SUM(H10:H38) -> 23 | I39: =SUM(I10:I38) -> 13.6 | J39: =SUM(J10:J38) -> 499226 | K39: =SUM(K10:K38) -> 54150 | L39: =SUM(L10:L38) -> 0 | M39: =SUM(M10:M38) -> 0 | N39: =SUM(N10:N38) -> 0 | O39: =SUM(O10:O38) -> 1675 | ... V39: =SUM(V10:V38) -> 650
A42: BLOCKS USED | D42: FED WT is this campaign's kg (linked to the RC Movement tab), not the block's lifetime. RESIKO is only a loss once the block is CLOSED.
A43: BATCH | B43: BLOCK LOC | C43: DATE OPEN | D43: DATE CLOSE | E43: STATE | F43: FED WT kg | G43: ARRV WT kg | H43: RESIKO kg | I43: RESIKO LOSS % | J43: BLOCK PRICE ₱/kg | K43: ACTUAL PRICE ₱/kg | L43: RESIKO PRICE ₱/kg | M43: IN PRICE SET
A44: JAN-26-BLK15 | B44: A-11A | C44: 46230 | D44: 46239 | E44: CLOSED | F44: ='RC Movement'!F78 -> 54941 | G44: 73379 | H44: 4366 | I44: =IF(AND(E44="CLOSED",G44>0),H44/G44,"") -> 0.059499312 | J44: 49 | K44: 52.0999 | L44: =IF(K44="","",K44-J44) -> 3.0999 | M44: Y
A45: JAN-26-BLK18 | B45: A-8B | C45: 46231 | D45: 46241 | E45: CLOSED | F45: ='RC Movement'!G78 -> 45579 | G45: 59220 | H45: 507 | I45: =IF(AND(E45="CLOSED",G45>0),H45/G45,"") -> 0.0085612969 | J45: 48.7509 | K45: 49.1719 | L45: =IF(K45="","",K45-J45) -> 0.421 | M45: Y
...

Sheet SEPTEMBER 2026
A1: SEPTEMBER 2026 — PLANT OPERATIONS
A2: 2026-08-29 → 2026-09-16 · 19 days · 4 rest · blue = database value · black = formula · green = link to another tab
A4: EOM ROLLUP | B4: RC FED (t) | C4: PRODUCED (t) | D4: YIELD | E4: LOSS | F4: WASTE (kg) | G4: WASTE % | H4: FED PRICE (₱/kg) | I4: ACTUAL FED PRICE (₱/kg) | J4: RESIKO COST (₱/kg) | K4: RESIKO LOSS | L4: PC COST (₱/kg) | M4: TRUE PC COST (₱/kg) | N4: fed kg in price set
A5: SEPTEMBER 2026 | B5: =D29/1000 -> 500.744 | C5: =E29/1000 -> 372.822 | D5: =E29/D29 -> 0.74453613 | E5: =1-D5 -> 0.25546387 | F5: =F29 -> 59283.5 | G5: =F29/E29 -> 0.15901288 | H5: =C29 -> 43.060268 | I5: =K48 -> 44.029833 | J5: =L48 -> 0.90595347 | K5: =I48 -> 0.020772716 | L5: =H5/D5 -> 57.835028 | M5: =IF(COUNTIF(M34:M47,"N")=0,I5/D5,"") | N5: =SUMPRODUCT((M34:M47="Y")*F34:F47) -> 362787
A8: DAY | C8: PRICE | D8: FED | E8: PRODUCED | F8: WASTE | H8: SHIFT | J8: GRADES | O8: WASTE STREAMS
A9: DATE | B9: DAY | C9: FED PRICE ₱/kg | D9: TTL FED kg | E9: TTL PROD kg | F9: WASTE kg | G9: WASTE % | H9: SHIFTS | I9: DT HRS | J9: 3X50 kg | K9: 6X50 kg | L9: 8X50 kg | M9: 2X6 kg | N9: 4X8 kg | O9: TRML 1 kg | P9: TRML 2 kg | Q9: RS1A kg | R9: RS1B kg | S9: RS2/3 kg | T9: RS5 kg | U9: BF kg | V9: GRITS kg
A10: 46263 | B10: Sat | C10: 41.0811 | D10: ='RC Movement'!E87 -> 12314 | E10: =SUM(J10:N10) -> 7506 | F10: =SUM(O10:V10) -> 1528.5 | G10: =IF(E10>0,F10/E10,"") -> 0.20363709 | H10: 1 | I10: 0 | J10: 5226 | K10: 2280 | O10: 55 | P10: 0.5 | Q10: 550 | R10: 550 | S10: 179 | T10: 74 | U10: 100 | V10: 20
A11: 46264 | B11: Sun | D11: ='RC Movement'!E88 -> 0 | E11: =SUM(J11:N11) -> 0 | F11: =SUM(O11:V11) -> 0 | G11: =IF(E11>0,F11/E11,"")
A12: 46265 | B12: Mon | D12: ='RC Movement'!E89 -> 0 | E12: =SUM(J12:N12) -> 0 | F12: =SUM(O12:V12) -> 0 | G12: =IF(E12>0,F12/E12,"")
A13: 46266 | B13: Tue | C13: 41.4406 | D13: ='RC Movement'!E90 -> 41867 | E13: =SUM(J13:N13) -> 25290 | F13: =SUM(O13:V13) -> 3212.5 | G13: =IF(E13>0,F13/E13,"") -> 0.12702649 | H13: 1 | I13: 1.58 | J13: 15600 | K13: 9690 | O13: 50 | P13: 0.5 | Q13: 1100 | R13: 1100 | S13: 608 | T13: 174 | U13: 150 | V13: 30
A14: 46267 | B14: Wed | C14: 41.2271 | D14: ='RC Movement'!E91 -> 28656 | E14: =SUM(J14:N14) -> 27990 | F14: =SUM(O14:V14) -> 3941.5 | G14: =IF(E14>0,F14/E14,"") -> 0.14081815 | H14: 1 | I14: 0.25 | J14: 17160 | K14: 10830 | O14: 75 | P14: 0.5 | Q14: 1650 | R14: 1108 | S14: 716 | T14: 239 | U14: 125 | V14: 28
A15: 46268 | B15: Thu | C15: 40.9802 | D15: ='RC Movement'!E92 -> 35299 | E15: =SUM(J15:N15) -> 27582 | F15: =SUM(O15:V15) -> 4230.5 | G15: =IF(E15>0,F15/E15,"") -> 0.15337902 | H15: 1 | I15: 1.97 | J15: 19032 | K15: 8550 | O15: 50 | P15: 0.5 | Q15: 1650 | R15: 1642 | S15: 569 | T15: 192 | U15: 100 | V15: 27
A16: 46269 | B16: Fri | C16: 41.2774 | D16: ='RC Movement'!E93 -> 31255 | E16: =SUM(J16:N16) -> 22768 | F16: =SUM(O16:V16) -> 3373.5 | G16: =IF(E16>0,F16/E16,"") -> 0.14816848 | H16: 1 | I16: 0.12 | J16: 13078 | K16: 9690 | O16: 75 | P16: 0.5 | Q16: 1100 | R16: 1100 | S16: 776 | T16: 167 | U16: 125 | V16: 30
A17: 46270 | B17: Sat | C17: 44.0171 | D17: ='RC Movement'!E94 -> 31007 | E17: =SUM(J17:N17) -> 27288 | F17: =SUM(O17:V17) -> 5403.5 | G17: =IF(E17>0,F17/E17,"") -> 0.19801744 | H17: 1 | I17: 0.17 | J17: 16458 | K17: 10830 | O17: 100 | P17: 0.5 | Q17: 2200 | R17: 2107 | S17: 657 | T17: 155 | U17: 155 | V17: 29
A18: 46271 | B18: Sun | D18: ='RC Movement'!E95 -> 0 | E18: =SUM(J18:N18) -> 0 | F18: =SUM(O18:V18) -> 0 | G18: =IF(E18>0,F18/E18,"")
A19: 46272 | B19: Mon | C19: 44.8498 | D19: ='RC Movement'!E96 -> 34406 | E19: =SUM(J19:N19) -> 27600 | F19: =SUM(O19:V19) -> 5062.5 | G19: =IF(E19>0,F19/E19,"") -> 0.18342391 | H19: 1 | I19: 0.17 | J19: 16770 | K19: 10830 | O19: 75 | P19: 0.5 | Q19: 2200 | R19: 1555 | S19: 872 | T19: 183 | U19: 150 | V19: 27
A20: 46273 | B20: Tue | C20: 43.7697 | D20: ='RC Movement'!E97 -> 38399 | E20: =SUM(J20:N20) -> 19838 | F20: =SUM(O20:V20) -> 3291.5 | G20: =IF(E20>0,F20/E20,"") -> 0.16591894 | H20: 1 | I20: 2.73 | J20: 12428 | K20: 7410 | O20: 55 | P20: 0.5 | Q20: 1100 | R20: 1100 | S20: 770 | T20: 140 | U20: 100 | V20: 26
A21: 46274 | B21: Wed | C21: 44.4955 | D21: ='RC Movement'!E98 -> 34480 | E21: =SUM(J21:N21) -> 27300 | F21: =SUM(O21:V21) -> 3622.5 | G21: =IF(E21>0,F21/E21,"") -> 0.13269231 | H21: 1 | I21: 0.08 | J21: 12480 | M21: 14820 | O21: 50 | P21: 0.5 | Q21: 1650 | R21: 1573 | S21: 50 | T21: 149 | U21: 120 | V21: 30
A22: 46275 | B22: Thu | C22: 46.0887 | D22: ='RC Movement'!E99 -> 31487 | E22: =SUM(J22:N22) -> 29480 | F22: =SUM(O22:V22) -> 3537.5 | G22: =IF(E22>0,F22/E22,"") -> 0.11999661 | H22: 1 | I22: 0.08 | J22: 13520 | M22: 15960 | O22: 75 | P22: 0.5 | Q22: 1650 | R22: 1481 | S22: 80 | T22: 98 | U22: 125 | V22: 28
A23: 46276 | B23: Fri | C23: 42.4726 | D23: ='RC Movement'!E100 -> 35468 | E23: =SUM(J23:N23) -> 24030 | F23: =SUM(O23:V23) -> 4069.5 | G23: =IF(E23>0,F23/E23,"") -> 0.16935081 | H23: 1 | I23: 1.45 | J23: 18330 | L23: 5700 | O23: 60 | P23: 0.5 | Q23: 1650 | R23: 1594 | S23: 526 | T23: 80 | U23: 130 | V23: 29
A24: 46277 | B24: Sat | C24: 42.8893 | D24: ='RC Movement'!E101 -> 34155 | E24: =SUM(J24:N24) -> 26412 | F24: =SUM(O24:V24) -> 3221.5 | G24: =IF(E24>0,F24/E24,"") -> 0.12197107 | H24: 1 | I24: 0.42 | J24: 19812 | L24: 6600 | O24: 75 | P24: 0.5 | Q24: 1100 | R24: 1100 | S24: 637 | T24: 129 | U24: 150 | V24: 30
A25: 46278 | B25: Sun | D25: ='RC Movement'!E102 -> 0 | E25: =SUM(J25:N25) -> 0 | F25: =SUM(O25:V25) -> 0 | G25: =IF(E25>0,F25/E25,"")
A26: 46279 | B26: Mon | C26: 43.9329 | D26: ='RC Movement'!E103 -> 36450 | E26: =SUM(J26:N26) -> 26460 | F26: =SUM(O26:V26) -> 4888.5 | G26: =IF(E26>0,F26/E26,"") -> 0.18475057 | H26: 1 | I26: 1.83 | J26: 20410 | L26: 6050 | O26: 50 | P26: 0.5 | Q26: 2200 | R26: 1739 | S26: 582 | T26: 114 | U26: 175 | V26: 28
A27: 46280 | B27: Tue | C27: 43.4503 | D27: ='RC Movement'!E104 -> 40041 | E27: =SUM(J27:N27) -> 25480 | F27: =SUM(O27:V27) -> 5452.5 | G27: =IF(E27>0,F27/E27,"") -> 0.21399137 | H27: 1 | I27: 0.53 | J27: 18330 | L27: 7150 | O27: 75 | P27: 0.5 | Q27: 2200 | R27: 2218 | S27: 678 | T27: 126 | U27: 125 | V27: 30
A28: 46281 | B28: Wed | C28: 42.7725 | D28: ='RC Movement'!E105 -> 35460 | E28: =SUM(J28:N28) -> 27798 | F28: =SUM(O28:V28) -> 4447.5 | G28: =IF(E28>0,F28/E28,"") -> 0.15999352 | H28: 1 | I28: 0.95 | J28: 20098 | L28: 7700 | O28: 50 | P28: 0.5 | Q28: 1650 | R28: 1709 | S28: 786 | T28: 125 | U28: 100 | V28: 27
A29: SEPTEMBER 2026 | B29: 19 d | C29: =SUMPRODUCT(C10:C28,D10:D28)/SUMIF(C10:C28,">0",D10:D28) -> 43.060268 | D29: =SUM(D10:D28) -> 500744 | E29: =SUM(E10:E28) -> 372822 | F29: =SUM(F10:F28) -> 59283.5 | G29: =IF(E29>0,F29/E29,"") -> 0.15901288 | H29: =SUM(H10:H28) -> 15 | I29: =SUM(I10:I28) -> 12.33 | J29: =SUM(J10:J28) -> 238732 | K29: =SUM(K10:K28) -> 70110 | L29: =SUM(L10:L28) -> 33200 | M29: =SUM(M10:M28) -> 30780 | N29: =SUM(N10:N28) -> 0 | O29: =SUM(O10:O28) -> 970 | ... V29: =SUM(V10:V28) -> 419
A32: BLOCKS USED | D32: FED WT is this campaign's kg (linked to the RC Movement tab), not the block's lifetime. RESIKO is only a loss once the block is CLOSED.
A33: BATCH | B33: BLOCK LOC | C33: DATE OPEN | D33: DATE CLOSE | E33: STATE | F33: FED WT kg | G33: ARRV WT kg | H33: RESIKO kg | I33: RESIKO LOSS % | J33: BLOCK PRICE ₱/kg | K33: ACTUAL PRICE ₱/kg | L33: RESIKO PRICE ₱/kg | M33: IN PRICE SET
A34: JULY-26-BLK13 | B34: C-6B | C34: 46258 | D34: 46263 | E34: CLOSED | F34: ='RC Movement'!F106 -> 6119 | G34: 41765 | H34: 328 | I34: =IF(AND(E34="CLOSED",G34>0),H34/G34,"") -> 0.0078534658 | J34: 39.5 | K34: 39.8127 | L34: =IF(K34="","",K34-J34) -> 0.3127 | M34: Y
A35: JULY-26-BLK5 | B35: A-17C | C35: 46259 | D35: 46275 | E35: CLOSED | F35: ='RC Movement'!G106 -> 52007 | G35: 74612 | H35: 727 | I35: =IF(AND(E35="CLOSED",G35>0),H35/G35,"") -> 0.009743741 | J35: 39.5013 | K35: 39.89 | L35: =IF(K35="","",K35-J35) -> 0.3887 | M35: Y
A36: SEPT-25-BLK4 | B36: D-7D | C36: 46259 | D36: 46268 | E36: CLOSED | F36: ='RC Movement'!H106 -> 31233 | G36: 64640 | H36: 1411 | I36: =IF(AND(E36="CLOSED",G36>0),H36/G36,"") -> 0.021828589 | J36: 44.6269 | K36: 45.6228 | L36: =IF(K36="","",K36-J36) -> 0.9959 | M36: Y
A37: JULY-26-BLK10 | B37: C-6A | C37: 46266 | D37: 46270 | E37: CLOSED | F37: ='RC Movement'!I106 -> 54490 | G37: 55060 | H37: 570 | I37: =IF(AND(E37="CLOSED",G37>0),H37/G37,"") -> 0.010352343 | J37: 39.5 | K37: 39.9132 | L37: =IF(K37="","",K37-J37) -> 0.4132 | M37: Y
A38: SEPTEMBER-26-FEED1 | B38: — | C38: 46267 | D38: 46269 | E38: CLOSED | F38: ='RC Movement'!J106 -> 19385 | G38: 19385 | H38: 0 | I38: =IF(AND(E38="CLOSED",G38>0),H38/G38,"") -> 0 | J38: 39 | K38: 39 | L38: =IF(K38="","",K38-J38) -> 0 | M38: Y
A39: NOV-25-BLK13 | B39: D-8A | C39: 46268 | D39: 46273 | E39: CLOSED | F39: ='RC Movement'!K106 -> 55330 | G39: 58195 | H39: 2865 | I39: =IF(AND(E39="CLOSED",G39>0),H39/G39,"") -> 0.049231034 | J39: 45.5432 | K39: 47.9015 | L39: =IF(K39="","",K39-J39) -> 2.3583 | M39: Y
A40: FEB-26-BLK12 | B40: A-6C | C40: 46270 | D40: 46275 | E40: CLOSED | F40: ='RC Movement'!L106 -> 52148 | G40: 53705 | H40: 1557 | I40: =IF(AND(E40="CLOSED",G40>0),H40/G40,"") -> 0.028991714 | J40: 48.6076 | K40: 50.0589 | L40: =IF(K40="","",K40-J40) -> 1.4513 | M40: Y
A41: SEPT-26-FEED2 | B41: — | C41: 46272 | D41: 46274 | E41: CLOSED | F41: ='RC Movement'!M106 -> 19170 | G41: 19170 | H41: 0 | I41: =IF(AND(E41="CLOSED",G41>0),H41/G41,"") -> 0 | J41: 39 | K41: 39 | L41: =IF(K41="","",K41-J41) -> 0 | M41: Y
A42: NOV-25-BLK12 | B42: D-8B | C42: 46274 | D42: 46279 | E42: CLOSED | F42: ='RC Movement'!N106 -> 53395 | G42: 55525 | H42: 2130 | I42: =IF(AND(E42="CLOSED",G42>0),H42/G42,"") -> 0.038361099 | J42: 45.5664 | K42: 47.3841 | L42: =IF(K42="","",K42-J42) -> 1.8177 | M42: Y
A43: FEB-26-BLK9 | B43: A-6B | C43: 46275 | E43: OPEN | F43: ='RC Movement'!O106 -> 34175 | G43: 52860 | I43: =IF(AND(E43="CLOSED",G43>0),H43/G43,"") | J43: 48.8077 | L43: =IF(K43="","",K43-J43) | M43: N
A44: SEPT-26-FEED3 | B44: — | C44: 46275 | D44: 46277 | E44: CLOSED | F44: ='RC Movement'!P106 -> 19510 | G44: 19510 | H44: 0 | I44: =IF(AND(E44="CLOSED",G44>0),H44/G44,"") -> 0 | J44: 39 | K44: 39 | L44: =IF(K44="","",K44-J44) -> 0 | M44: Y
A45: JUNE-26-BLK2 | B45: A-17B | C45: 46276 | E45: OPEN | F45: ='RC Movement'!Q106 -> 61713 | G45: 75577 | I45: =IF(AND(E45="CLOSED",G45>0),H45/G45,"") | J45: 39.9167 | L45: =IF(K45="","",K45-J45) | M45: N
...

Sheet RC Movement
A1: RC MOVEMENT — Q3 2026
A2: One table per campaign, stacked. Blue = database value · black = formula · green = link to another tab. kg fed by block per day; the footer is this campaign's kg, the block's delivered ₱/kg, its resiko loss and its actual ₱/kg.
A4: JULY 2026 · 2026-06-30 → 2026-08-01 · 33 days · 19 blocks
A5: # | B5: DATE | C5: DAY | D5: FED ₱/kg | E5: TOTAL FED kg | F5: FEB-26-BLK4 | G5: JULY-25-BLK9 | H5: MARCH-26-BLK26 | I5: MARCH-26-BLK9 | J5: OCT-25-BLK25 | K5: JUNE-26-FEED7 | L5: AUG-25-BLK2 | M5: JULY-26-FEED1 | N5: AUG-25-BLK4 | O5: FEB-26-BLK1 | P5: JAN-26-BLK3 | Q5: NOV-25-BLK7 | R5: JAN-26-BLK1 | S5: JULY-26-FEED2 | T5: JAN-26-BLK19 | U5: OCT-25-BLK10 | V5: JAN-26-BLK15 | W5: JAN-26-BLK18 | X5: JAN-26-BLK22
F6: A-7C | G6: C-11B | H6: A-5B | I6: C-6A | J6: D-7B | K6: — | L6: C-12A | M6: FOR FEEDING | N6: C-12B | O6: A-7B | P6: A-9B | Q6: D-15A | R6: A-9A | S6: — | T6: A-8C | U6: D-7C | V6: A-11A | W6: A-8B | X6: A-7A
A7: 1 | B7: 46203 | C7: Tue | D7: 44.0221 | E7: =SUM(F7:X7) -> 18963 | F7: 2507 | G7: 11384 | H7: 1203 | I7: 1414 | J7: 2455
A8: 2 | B8: 46204 | C8: Wed | D8: 42.7426 | E8: =SUM(F8:X8) -> 36226 | F8: 5658 | G8: 12473 | H8: 2576 | J8: 5519 | K8: 10000
A9: 3 | B9: 46205 | C9: Thu | D9: 43.3234 | E9: =SUM(F9:X9) -> 30992 | F9: 5430 | G9: 11831 | H9: 2754 | J9: 4977 | K9: 6000
A10: 4 | B10: 46206 | C10: Fri | D10: 44.246 | E10: =SUM(F10:X10) -> 33040 | F10: 7142 | G10: 11686 | H10: 3784 | J10: 7003 | K10: 3425
A11: 5 | B11: 46207 | C11: Sat | D11: 44.6338 | E11: =SUM(F11:X11) -> 35066 | F11: 6629 | G11: 11694 | H11: 3541 | J11: 7119 | L11: 6083
A12: 6 | B12: 46208 | C12: Sun | E12: =SUM(F12:X12) -> 0
A13: 7 | B13: 46209 | C13: Mon | D13: 45.2625 | E13: =SUM(F13:X13) -> 33892 | F13: 6834 | H13: 3690 | J13: 6792 | L13: 16576
A14: 8 | B14: 46210 | C14: Tue | D14: 45.4369 | E14: =SUM(F14:X14) -> 32944 | F14: 7658 | H14: 3650 | J14: 6501 | L14: 15135
A15: 9 | B15: 46211 | C15: Wed | D15: 44.6154 | E15: =SUM(F15:X15) -> 36171 | F15: 7463 | H15: 3598 | J15: 6824 | L15: 15286 | M15: 3000
A16: 10 | B16: 46212 | C16: Thu | D16: 41.1244 | E16: =SUM(F16:X16) -> 38644 | F16: 2172 | H16: 1257 | J16: 2042 | M16: 16605 | N16: 16568
A17: 11 | B17: 46213 | C17: Fri | D17: 45.7043 | E17: =SUM(F17:X17) -> 36541 | F17: 7747 | H17: 3887 | J17: 7845 | N17: 17062
A18: 12 | B18: 46214 | C18: Sat | D18: 45.2004 | E18: =SUM(F18:X18) -> 37409 | F18: 4710 | H18: 2777 | J18: 9432 | N18: 20490
A19: 13 | B19: 46215 | C19: Sun | E19: =SUM(F19:X19) -> 0
A20: 14 | B20: 46216 | C20: Mon | D20: 48.4234 | E20: =SUM(F20:X20) -> 25492 | O20: 16154 | P20: 9338
A21: 15 | B21: 46217 | C21: Tue | D21: 48.1897 | E21: =SUM(F21:X21) -> 42356 | O21: 20553 | P21: 21803
A22: 16 | B22: 46218 | C22: Wed | D22: 48.2329 | E22: =SUM(F22:X22) -> 10366 | O22: 5315 | P22: 5051
A23: 17 | B23: 46219 | C23: Thu | D23: 48.1946 | E23: =SUM(F23:X23) -> 19966 | O23: 9751 | P23: 10215
A24: 18 | B24: 46220 | C24: Fri | E24: =SUM(F24:X24) -> 0
A25: 19 | B25: 46221 | C25: Sat | E25: =SUM(F25:X25) -> 0
A26: 20 | B26: 46222 | C26: Sun | E26: =SUM(F26:X26) -> 0
A27: 21 | B27: 46223 | C27: Mon | D27: 45.4203 | E27: =SUM(F27:X27) -> 22126 | O27: 2346 | P27: 10921 | Q27: 8859
A28: 22 | B28: 46224 | C28: Tue | D28: 41.962 | E28: =SUM(F28:X28) -> 31699 | P28: 4646 | Q28: 11167 | R28: 5886 | S28: 10000
A29: 23 | B29: 46225 | C29: Wed | D29: 44.3621 | E29: =SUM(F29:X29) -> 40763 | Q29: 6731 | R29: 16229 | S29: 8925 | T29: 8878
A30: 24 | B30: 46226 | C30: Thu | D30: 46.7782 | E30: =SUM(F30:X30) -> 42142 | Q30: 9080 | R30: 15900 | T30: 17162
A31: 25 | B31: 46227 | C31: Fri | D31: 46.2208 | E31: =SUM(F31:X31) -> 41500 | Q31: 6443 | R31: 12237 | T31: 12235 | U31: 10585
A32: 26 | B32: 46228 | C32: Sat | D32: 45.6054 | E32: =SUM(F32:X32) -> 31019 | Q32: 3617 | R32: 5952 | T32: 6144 | U32: 15306
A33: 27 | B33: 46229 | C33: Sun | E33: =SUM(F33:X33) -> 0
A34: 28 | B34: 46230 | C34: Mon | D34: 46.5932 | E34: =SUM(F34:X34) -> 42584 | R34: 9816 | T34: 9408 | U34: 18796 | V34: 4564
A35: 29 | B35: 46231 | C35: Tue | D35: 46.4774 | E35: =SUM(F35:X35) -> 30499 | T35: 4677 | U35: 15452 | V35: 3143 | W35: 2114 | X35: 5113
A36: 30 | B36: 46232 | C36: Wed | D36: 48.1486 | E36: =SUM(F36:X36) -> 30834 | U36: 3339 | V36: 6365 | W36: 11020 | X36: 10110
A37: 31 | B37: 46233 | C37: Thu | E37: =SUM(F37:X37) -> 0
A38: 32 | B38: 46234 | C38: Fri | E38: =SUM(F38:X38) -> 0
A39: 33 | B39: 46235 | C39: Sat | E39: =SUM(F39:X39) -> 0
B40: FED kg (this campaign) | D40: =SUMPRODUCT(D7:D39,E7:E39)/SUMIF(D7:D39,">0",E7:E39) -> 45.337719 | E40: =SUM(E7:E39) -> 781234 | F40: =SUM(F7:F39) -> 63950 | G40: =SUM(G7:G39) -> 59068 | H40: =SUM(H7:H39) -> 32717 | I40: =SUM(I7:I39) -> 1414 | J40: =SUM(J7:J39) -> 66509 | K40: =SUM(K7:K39) -> 19425 | L40: =SUM(L7:L39) -> 53080 | ... X40: =SUM(X7:X39) -> 15223
B41: ₱/KG (block price) | F41: =IF('JULY 2026'!J48="","",'JULY 2026'!J48) -> 49 | G41: =IF('JULY 2026'!J49="","",'JULY 2026'!J49) -> 41.913 | H41: =IF('JULY 2026'!J50="","",'JULY 2026'!J50) -> 47.6616 | I41: =IF('JULY 2026'!J51="","",'JULY 2026'!J51) -> 48.25 | J41: =IF('JULY 2026'!J52="","",'JULY 2026'!J52) -> 44.5 | K41: =IF('JULY 2026'!J53="","",'JULY 2026'!J53) -> 38 | L41: =IF('JULY 2026'!J54="","",'JULY 2026'!J54) -> 43.5 | M41: =IF('JULY 2026'!J55="","",'JULY 2026'!J55) -> 36 | N41: =IF('JULY 2026'!J56="","",'JULY 2026'!J56) -> 44.3158 | O41: =IF('JULY 2026'!J57="","",'JULY 2026'!J57) -> 49 | P41: =IF('JULY 2026'!J58="","",'JULY 2026'!J58) -> 47.4258 | Q41: =IF('JULY 2026'!J59="","",'JULY 2026'!J59) -> 42 | R41: =IF('JULY 2026'!J60="","",'JULY 2026'!J60) -> 47.7061 | S41: =IF('JULY 2026'!J61="","",'JULY 2026'!J61) -> 36 | T41: =IF('JULY 2026'!J62="","",'JULY 2026'!J62) -> 48.4466 | U41: =IF('JULY 2026'!J63="","",'JULY 2026'!J63) -> 44.5 | V41: =IF('JULY 2026'!J64="","",'JULY 2026'!J64) -> 49 | W41: =IF('JULY 2026'!J65="","",'JULY 2026'!J65) -> 48.7509 | X41: =IF('JULY 2026'!J66="","",'JULY 2026'!J66) -> 48.1612
...

Sheet Checks
A1: CHECKS — the workbook's formulas against the database's own figures
A2: WORKBOOK is a live link to the formula cell. DATABASE is the figure the Blackwood views published on 2026-09-17. A row reads CHECK when they differ by more than the tolerance.
A4: CAMPAIGN | B4: FIGURE | C4: WORKBOOK | D4: DATABASE | E4: DIFFERENCE | F4: STATUS | G4: TOLERANCE
A5: JULY 2026 | B5: RC fed kg | C5: =IF('JULY 2026'!D43="","",'JULY 2026'!D43) -> 781234 | D5: 781234 | E5: =IF(OR(C5="",D5=""),"",C5-D5) -> 0 | F5: =IF(AND(C5="",D5=""),"OK (blank on purpose)",IF(OR(C5="",D5=""),"CHECK",IF(ABS(E5)<=G5,"OK","CHECK"))) -> OK | G5: 0.5
A6: JULY 2026 | B6: Produced kg | C6: =IF('JULY 2026'!E43="","",'JULY 2026'!E43) -> 621201 | D6: 621201 | E6: =IF(OR(C6="",D6=""),"",C6-D6) -> 0 | F6: =IF(AND(C6="",D6=""),"OK (blank on purpose)",IF(OR(C6="",D6=""),"CHECK",IF(ABS(E6)<=G6,"OK","CHECK"))) -> OK | G6: 0.5
A7: JULY 2026 | B7: Yield | C7: =IF('JULY 2026'!D5="","",'JULY 2026'!D5) -> 0.79515356 | D7: 0.795154 | E7: =IF(OR(C7="",D7=""),"",C7-D7) -> -4.3525499e-07 | F7: =IF(AND(C7="",D7=""),"OK (blank on purpose)",IF(OR(C7="",D7=""),"CHECK",IF(ABS(E7)<=G7,"OK","CHECK"))) -> OK | G7: 5e-05
A8: JULY 2026 | B8: Loss | C8: =IF('JULY 2026'!E5="","",'JULY 2026'!E5) -> 0.20484644 | D8: 0.204846 | E8: =IF(OR(C8="",D8=""),"",C8-D8) -> 4.3525499e-07 | F8: =IF(AND(C8="",D8=""),"OK (blank on purpose)",IF(OR(C8="",D8=""),"CHECK",IF(ABS(E8)<=G8,"OK","CHECK"))) -> OK | G8: 5e-05
A9: JULY 2026 | B9: Waste kg | C9: =IF('JULY 2026'!F5="","",'JULY 2026'!F5) -> 106506.5 | D9: 106506.5 | E9: =IF(OR(C9="",D9=""),"",C9-D9) -> 0 | F9: =IF(AND(C9="",D9=""),"OK (blank on purpose)",IF(OR(C9="",D9=""),"CHECK",IF(ABS(E9)<=G9,"OK","CHECK"))) -> OK | G9: 0.05
A10: JULY 2026 | B10: Waste % | C10: =IF('JULY 2026'!G5="","",'JULY 2026'!G5) -> 0.17145256 | D10: 0.171453 | E10: =IF(OR(C10="",D10=""),"",C10-D10) -> -4.4277617e-07 | F10: =IF(AND(C10="",D10=""),"OK (blank on purpose)",IF(OR(C10="",D10=""),"CHECK",IF(ABS(E10)<=G10,"OK","CHECK"))) -> OK | G10: 5e-05
A11: JULY 2026 | B11: Fed price | C11: =IF('JULY 2026'!H5="","",'JULY 2026'!H5) -> 45.337719 | D11: 45.3377 | E11: =IF(OR(C11="",D11=""),"",C11-D11) -> 1.8985477e-05 | F11: =IF(AND(C11="",D11=""),"OK (blank on purpose)",IF(OR(C11="",D11=""),"CHECK",IF(ABS(E11)<=G11,"OK","CHECK"))) -> OK | G11: 0.005
A12: JULY 2026 | B12: Actual fed price | C12: =IF('JULY 2026'!I5="","",'JULY 2026'!I5) -> 47.577998 | D12: 47.578 | E12: =IF(OR(C12="",D12=""),"",C12-D12) -> -2.2051012e-06 | F12: =IF(AND(C12="",D12=""),"OK (blank on purpose)",IF(OR(C12="",D12=""),"CHECK",IF(ABS(E12)<=G12,"OK","CHECK"))) -> OK | G12: 0.005
A13: JULY 2026 | B13: Resiko cost | C13: =IF('JULY 2026'!J5="","",'JULY 2026'!J5) -> 2.1714893 | D13: 2.1715 | E13: =IF(OR(C13="",D13=""),"",C13-D13) -> -1.0675119e-05 | F13: =IF(AND(C13="",D13=""),"OK (blank on purpose)",IF(OR(C13="",D13=""),"CHECK",IF(ABS(E13)<=G13,"OK","CHECK"))) -> OK | G13: 0.005
A14: JULY 2026 | B14: Resiko loss | C14: =IF('JULY 2026'!K5="","",'JULY 2026'!K5) -> 0.044997601 | D14: 0.044998 | E14: =IF(OR(C14="",D14=""),"",C14-D14) -> -3.9939152e-07 | F14: =IF(AND(C14="",D14=""),"OK (blank on purpose)",IF(OR(C14="",D14=""),"CHECK",IF(ABS(E14)<=G14,"OK","CHECK"))) -> OK | G14: 5e-05
A15: JULY 2026 | B15: PC cost | C15: =IF('JULY 2026'!L5="","",'JULY 2026'!L5) -> 57.017564 | D15: 57.0176 | E15: =IF(OR(C15="",D15=""),"",C15-D15) -> -3.63549e-05 | F15: =IF(AND(C15="",D15=""),"OK (blank on purpose)",IF(OR(C15="",D15=""),"CHECK",IF(ABS(E15)<=G15,"OK","CHECK"))) -> OK | G15: 0.005
A16: JULY 2026 | B16: True PC cost | C16: =IF('JULY 2026'!M5="","",'JULY 2026'!M5) -> 59.83498 | D16: 59.835 | E16: =IF(OR(C16="",D16=""),"",C16-D16) -> -1.980953e-05 | F16: =IF(AND(C16="",D16=""),"OK (blank on purpose)",IF(OR(C16="",D16=""),"CHECK",IF(ABS(E16)<=G16,"OK","CHECK"))) -> OK | G16: 0.005
A17: JULY 2026 | B17: Fed kg in price set | C17: =IF('JULY 2026'!N5="","",'JULY 2026'!N5) -> 781234 | D17: 781234 | E17: =IF(OR(C17="",D17=""),"",C17-D17) -> 0 | F17: =IF(AND(C17="",D17=""),"OK (blank on purpose)",IF(OR(C17="",D17=""),"CHECK",IF(ABS(E17)<=G17,"OK","CHECK"))) -> OK | G17: 0.5
A18: AUGUST 2026 | B18: RC fed kg | C18: =IF('AUGUST 2026'!D39="","",'AUGUST 2026'!D39) -> 697313 | D18: 697313 | E18: =IF(OR(C18="",D18=""),"",C18-D18) -> 0 | F18: =IF(AND(C18="",D18=""),"OK (blank on purpose)",IF(OR(C18="",D18=""),"CHECK",IF(ABS(E18)<=G18,"OK","CHECK"))) -> OK | G18: 0.5
A19: AUGUST 2026 | B19: Produced kg | C19: =IF('AUGUST 2026'!E39="","",'AUGUST 2026'!E39) -> 553376 | D19: 553376 | E19: =IF(OR(C19="",D19=""),"",C19-D19) -> 0 | F19: =IF(AND(C19="",D19=""),"OK (blank on purpose)",IF(OR(C19="",D19=""),"CHECK",IF(ABS(E19)<=G19,"OK","CHECK"))) -> OK | G19: 0.5
A20: AUGUST 2026 | B20: Yield | C20: =IF('AUGUST 2026'!D5="","",'AUGUST 2026'!D5) -> 0.79358337 | D20: 0.793583 | E20: =IF(OR(C20="",D20=""),"",C20-D20) -> 3.6930475e-07 | F20: =IF(AND(C20="",D20=""),"OK (blank on purpose)",IF(OR(C20="",D20=""),"CHECK",IF(ABS(E20)<=G20,"OK","CHECK"))) -> OK | G20: 5e-05
A21: AUGUST 2026 | B21: Loss | C21: =IF('AUGUST 2026'!E5="","",'AUGUST 2026'!E5) -> 0.20641663 | D21: 0.206417 | E21: =IF(OR(C21="",D21=""),"",C21-D21) -> -3.6930475e-07 | F21: =IF(AND(C21="",D21=""),"OK (blank on purpose)",IF(OR(C21="",D21=""),"CHECK",IF(ABS(E21)<=G21,"OK","CHECK"))) -> OK | G21: 5e-05
A22: AUGUST 2026 | B22: Waste kg | C22: =IF('AUGUST 2026'!F5="","",'AUGUST 2026'!F5) -> 78954.5 | D22: 78954.5 | E22: =IF(OR(C22="",D22=""),"",C22-D22) -> 0 | F22: =IF(AND(C22="",D22=""),"OK (blank on purpose)",IF(OR(C22="",D22=""),"CHECK",IF(ABS(E22)<=G22,"OK","CHECK"))) -> OK | G22: 0.05
A23: AUGUST 2026 | B23: Waste % | C23: =IF('AUGUST 2026'!G5="","",'AUGUST 2026'!G5) -> 0.14267785 | D23: 0.142678 | E23: =IF(OR(C23="",D23=""),"",C23-D23) -> -1.4624415e-07 | F23: =IF(AND(C23="",D23=""),"OK (blank on purpose)",IF(OR(C23="",D23=""),"CHECK",IF(ABS(E23)<=G23,"OK","CHECK"))) -> OK | G23: 5e-05
A24: AUGUST 2026 | B24: Fed price | C24: =IF('AUGUST 2026'!H5="","",'AUGUST 2026'!H5) -> 42.772035 | D24: 42.772 | E24: =IF(OR(C24="",D24=""),"",C24-D24) -> 3.5340227e-05 | F24: =IF(AND(C24="",D24=""),"OK (blank on purpose)",IF(OR(C24="",D24=""),"CHECK",IF(ABS(E24)<=G24,"OK","CHECK"))) -> OK | G24: 0.005
A25: AUGUST 2026 | B25: Actual fed price | C25: =IF('AUGUST 2026'!I5="","",'AUGUST 2026'!I5) -> 43.939216 | D25: 43.9392 | E25: =IF(OR(C25="",D25=""),"",C25-D25) -> 1.5615943e-05 | F25: =IF(AND(C25="",D25=""),"OK (blank on purpose)",IF(OR(C25="",D25=""),"CHECK",IF(ABS(E25)<=G25,"OK","CHECK"))) -> OK | G25: 0.005
A26: AUGUST 2026 | B26: Resiko cost | C26: =IF('AUGUST 2026'!J5="","",'AUGUST 2026'!J5) -> 1.0842165 | D26: 1.0842 | E26: =IF(OR(C26="",D26=""),"",C26-D26) -> 1.6485152e-05 | F26: =IF(AND(C26="",D26=""),"OK (blank on purpose)",IF(OR(C26="",D26=""),"CHECK",IF(ABS(E26)<=G26,"OK","CHECK"))) -> OK | G26: 0.005
A27: AUGUST 2026 | B27: Resiko loss | C27: =IF('AUGUST 2026'!K5="","",'AUGUST 2026'!K5) -> 0.024606567 | D27: 0.024607 | E27: =IF(OR(C27="",D27=""),"",C27-D27) -> -4.333078e-07 | F27: =IF(AND(C27="",D27=""),"OK (blank on purpose)",IF(OR(C27="",D27=""),"CHECK",IF(ABS(E27)<=G27,"OK","CHECK"))) -> OK | G27: 5e-05
A28: AUGUST 2026 | B28: PC cost | C28: =IF('AUGUST 2026'!L5="","",'AUGUST 2026'!L5) -> 53.897343 | D28: 53.8974 | E28: =IF(OR(C28="",D28=""),"",C28-D28) -> -5.663997e-05 | F28: =IF(AND(C28="",D28=""),"OK (blank on purpose)",IF(OR(C28="",D28=""),"CHECK",IF(ABS(E28)<=G28,"OK","CHECK"))) -> OK | G28: 0.005
A29: AUGUST 2026 | B29: True PC cost | C29: =IF('AUGUST 2026'!M5="","",'AUGUST 2026'!M5) -> 55.368115 | D29: 55.3681 | E29: =IF(OR(C29="",D29=""),"",C29-D29) -> 1.5456399e-05 | F29: =IF(AND(C29="",D29=""),"OK (blank on purpose)",IF(OR(C29="",D29=""),"CHECK",IF(ABS(E29)<=G29,"OK","CHECK"))) -> OK | G29: 0.005
A30: AUGUST 2026 | B30: Fed kg in price set | C30: =IF('AUGUST 2026'!N5="","",'AUGUST 2026'!N5) -> 697313 | D30: 697313 | E30: =IF(OR(C30="",D30=""),"",C30-D30) -> 0 | F30: =IF(AND(C30="",D30=""),"OK (blank on purpose)",IF(OR(C30="",D30=""),"CHECK",IF(ABS(E30)<=G30,"OK","CHECK"))) -> OK | G30: 0.5
A31: SEPTEMBER 2026 | B31: RC fed kg | C31: =IF('SEPTEMBER 2026'!D29="","",'SEPTEMBER 2026'!D29) -> 500744 | D31: 500744 | E31: =IF(OR(C31="",D31=""),"",C31-D31) -> 0 | F31: =IF(AND(C31="",D31=""),"OK (blank on purpose)",IF(OR(C31="",D31=""),"CHECK",IF(ABS(E31)<=G31,"OK","CHECK"))) -> OK | G31: 0.5
A32: SEPTEMBER 2026 | B32: Produced kg | C32: =IF('SEPTEMBER 2026'!E29="","",'SEPTEMBER 2026'!E29) -> 372822 | D32: 372822 | E32: =IF(OR(C32="",D32=""),"",C32-D32) -> 0 | F32: =IF(AND(C32="",D32=""),"OK (blank on purpose)",IF(OR(C32="",D32=""),"CHECK",IF(ABS(E32)<=G32,"OK","CHECK"))) -> OK | G32: 0.5
A33: SEPTEMBER 2026 | B33: Yield | C33: =IF('SEPTEMBER 2026'!D5="","",'SEPTEMBER 2026'!D5) -> 0.74453613 | D33: 0.744536 | E33: =IF(OR(C33="",D33=""),"",C33-D33) -> 1.3023821e-07 | F33: =IF(AND(C33="",D33=""),"OK (blank on purpose)",IF(OR(C33="",D33=""),"CHECK",IF(ABS(E33)<=G33,"OK","CHECK"))) -> OK | G33: 5e-05
A34: SEPTEMBER 2026 | B34: Loss | C34: =IF('SEPTEMBER 2026'!E5="","",'SEPTEMBER 2026'!E5) -> 0.25546387 | D34: 0.255464 | E34: =IF(OR(C34="",D34=""),"",C34-D34) -> -1.3023821e-07 | F34: =IF(AND(C34="",D34=""),"OK (blank on purpose)",IF(OR(C34="",D34=""),"CHECK",IF(ABS(E34)<=G34,"OK","CHECK"))) -> OK | G34: 5e-05
A35: SEPTEMBER 2026 | B35: Waste kg | C35: =IF('SEPTEMBER 2026'!F5="","",'SEPTEMBER 2026'!F5) -> 59283.5 | D35: 59283.5 | E35: =IF(OR(C35="",D35=""),"",C35-D35) -> 0 | F35: =IF(AND(C35="",D35=""),"OK (blank on purpose)",IF(OR(C35="",D35=""),"CHECK",IF(ABS(E35)<=G35,"OK","CHECK"))) -> OK | G35: 0.05
A36: SEPTEMBER 2026 | B36: Waste % | C36: =IF('SEPTEMBER 2026'!G5="","",'SEPTEMBER 2026'!G5) -> 0.15901288 | D36: 0.159013 | E36: =IF(OR(C36="",D36=""),"",C36-D36) -> -1.1985881e-07 | F36: =IF(AND(C36="",D36=""),"OK (blank on purpose)",IF(OR(C36="",D36=""),"CHECK",IF(ABS(E36)<=G36,"OK","CHECK"))) -> OK | G36: 5e-05
A37: SEPTEMBER 2026 | B37: Fed price | C37: =IF('SEPTEMBER 2026'!H5="","",'SEPTEMBER 2026'!H5) -> 43.060268 | D37: 43.0603 | E37: =IF(OR(C37="",D37=""),"",C37-D37) -> -3.1916309e-05 | F37: =IF(AND(C37="",D37=""),"OK (blank on purpose)",IF(OR(C37="",D37=""),"CHECK",IF(ABS(E37)<=G37,"OK","CHECK"))) -> OK | G37: 0.005
A38: SEPTEMBER 2026 | B38: Actual fed price | C38: =IF('SEPTEMBER 2026'!I5="","",'SEPTEMBER 2026'!I5) -> 44.029833 | D38: 44.0298 | E38: =IF(OR(C38="",D38=""),"",C38-D38) -> 3.2528178e-05 | F38: =IF(AND(C38="",D38=""),"OK (blank on purpose)",IF(OR(C38="",D38=""),"CHECK",IF(ABS(E38)<=G38,"OK","CHECK"))) -> OK | G38: 0.005
A39: SEPTEMBER 2026 | B39: Resiko cost | C39: =IF('SEPTEMBER 2026'!J5="","",'SEPTEMBER 2026'!J5) -> 0.90595347 | D39: 0.906 | E39: =IF(OR(C39="",D39=""),"",C39-D39) -> -4.6531979e-05 | F39: =IF(AND(C39="",D39=""),"OK (blank on purpose)",IF(OR(C39="",D39=""),"CHECK",IF(ABS(E39)<=G39,"OK","CHECK"))) -> OK | G39: 0.005
A40: SEPTEMBER 2026 | B40: Resiko loss | C40: =IF('SEPTEMBER 2026'!K5="","",'SEPTEMBER 2026'!K5) -> 0.020772716 | D40: 0.020773 | E40: =IF(OR(C40="",D40=""),"",C40-D40) -> -2.8444625e-07 | F40: =IF(AND(C40="",D40=""),"OK (blank on purpose)",IF(OR(C40="",D40=""),"CHECK",IF(ABS(E40)<=G40,"OK","CHECK"))) -> OK | G40: 5e-05
A41: SEPTEMBER 2026 | B41: PC cost | C41: =IF('SEPTEMBER 2026'!L5="","",'SEPTEMBER 2026'!L5) -> 57.835028 | D41: 57.835 | E41: =IF(OR(C41="",D41=""),"",C41-D41) -> 2.8193883e-05 | F41: =IF(AND(C41="",D41=""),"OK (blank on purpose)",IF(OR(C41="",D41=""),"CHECK",IF(ABS(E41)<=G41,"OK","CHECK"))) -> OK | G41: 0.005
...
